<?xml version="1.0" ?>
<!-- =================================================================================== -->
<!-- |    This document was autogenerated by xacro from kuka_robot.urdf.xacro          | -->
<!-- |    EDITING THIS FILE BY HAND IS NOT RECOMMENDED                                 | -->
<!-- =================================================================================== -->
<robot name="kuka_lwr" xmlns:xacro="http://ros.org/wiki/xacro">
  <!-- utils /-->
  <!-- Little helper macro to define the inertia matrix needed for links. -->
  <!-- length is along the y-axis! -->
  <material name="Kuka/DarkGrey">
    <color rgba="0.3 0.3 0.3 1.0"/>
  </material>
  <material name="Kuka/LightGrey">
    <color rgba="0.8 0.8 0.8 1.0"/>
  </material>
  <material name="Kuka/Red">
    <color rgba="0.3 0.3 0.3 1.0"/>
  </material>
  <material name="Kuka/Black">
    <color rgba="0 0 0 1.0"/>
  </material>
  <material name="Kuka/Orange">
    <color rgba="1.0 0.487 0 1.0"/>
  </material>
  <material name="Kuka/Silver">
    <color rgba="1.0 1.0 1.0 1.0"/>
  </material>
  <material name="Kuka/Grey">
    <color rgba="0.7 0.7 0.7 1.0"/>
  </material>
  <material name="Kuka/Blue">
    <color rgba="0.0 0.0 0.8 1.0"/>
  </material>
  <!-- gazebo and transmission models /-->
  <!-- properties /-->
  <!-- reflex to stiffness -->
  <!-- URDF model with default base_link (world)-->
  <link name="world"/>
  <gazebo reference="world">
    <static>true</static>
    <turnGravityOff>true</turnGravityOff>
  </gazebo>
  <!-- First (shoulder) element of the arm. Fixed to its parent. -->
  <joint name="kuka_lwr_base_joint" type="fixed">
    <origin rpy="0 0 0" xyz="0 0 0"/>
    <parent link="world"/>
    <child link="kuka_lwr_base_link"/>
  </joint>
  <link name="kuka_lwr_base_link">
    <inertial>
      <mass value="2.0"/>
      <origin xyz="0 0 0.055"/>
      <inertia ixx="0.00381666666667" ixy="0" ixz="0" iyy="0.0036" iyz="0" izz="0.00381666666667"/>
    </inertial>
    <visual>
      <origin rpy="0 0 3.14159265359" xyz="0 0 0"/>
      <geometry>
        <mesh filename="package://iit-kuka_lwr-ros-pkg/meshes_arm/arm_base.dae"/>
      </geometry>
      <material name="Kuka/Orange"/>
    </visual>
    <collision>
      <origin rpy="0 0 3.14159265359" xyz="0 0 0.055"/>
      <geometry>
        <!-- <mesh filename="package://iit-kuka_lwr-ros-pkg/meshes/convex/arm_base_convex.stl"/> -->
        <cylinder length="0.11" radius="0.07"/>
      </geometry>
    </collision>
  </link>
  <!-- Second segment of the arm. Joint along z-axis -->
  <joint name="kuka_lwr_0_joint" type="revolute">
    <origin rpy="0 0 0" xyz="0 0 0.11"/>
    <axis xyz="0 0 1"/>
    <limit effort="176" lower="-2.96705972839" upper="2.96705972839" velocity="1.91986217719"/>
    <dynamics damping="1.0" friction="10.0"/>
    <parent link="kuka_lwr_base_link"/>
    <child link="kuka_lwr_1_link"/>
  </joint>
  <!-- 			LINK 1 			-->
  <link name="kuka_lwr_1_link">
    <inertial>
      <mass value="2.0"/>
      <origin rpy="0 0 0" xyz="0 -0.06 0.130"/>
      <inertia ixx="0.0136666666667" ixy="0" ixz="0" iyy="0.003" iyz="0" izz="0.0118666666667"/>
    </inertial>
    <visual>
      <origin rpy="0 0 3.14159265359" xyz="0 0 0"/>
      <geometry>
        <mesh filename="package://iit-kuka_lwr-ros-pkg/meshes_arm/arm_segment_a.dae"/>
      </geometry>
      <material name="Orange"/>
    </visual>
    <collision>
      <origin rpy="0 0 0" xyz="0 0 0.0"/>
      <geometry>
        <!--mesh filename="package://iit-kuka_lwr-ros-pkg/meshes/convex/arm_segment_a_convex.stl"/-->
        <sphere radius="0.07"/>
      </geometry>
    </collision>
    <collision>
      <origin rpy="0 0 0" xyz="0 0.06 0.2"/>
      <geometry>
        <sphere radius="0.07"/>
      </geometry>
    </collision>
    <collision>
      <origin rpy="-0.291 0 0" xyz="0 0.03 0.1"/>
      <geometry>
        <cylinder length="0.208" radius="0.07"/>
      </geometry>
    </collision>
  </link>
  <!-- Third segment of the arm. Joint along y-axis -->
  <joint name="kuka_lwr_1_joint" type="revolute">
    <origin rpy="0 0 0" xyz="0 0 0.2005"/>
    <axis xyz="0 -1 0"/>
    <limit effort="176" lower="-2.09439510239" upper="2.09439510239" velocity="1.91986217719"/>
    <dynamics damping="1.0" friction="10.0"/>
    <parent link="kuka_lwr_1_link"/>
    <child link="kuka_lwr_2_link"/>
  </joint>
  <!-- 			LINK 2 			-->
  <link name="kuka_lwr_2_link">
    <inertial>
      <mass value="2.0"/>
      <origin rpy="0 0 0" xyz="0 0.06 0.07"/>
      <inertia ixx="0.0136666666667" ixy="0" ixz="0" iyy="0.003" iyz="0" izz="0.0118666666667"/>
    </inertial>
    <visual>
      <origin rpy="3.14159265359 0 3.14159265359" xyz="0 0 0.2"/>
      <geometry>
        <mesh filename="package://iit-kuka_lwr-ros-pkg/meshes_arm/arm_segment_b.dae"/>
      </geometry>
      <material name="Orange"/>
    </visual>
    <collision>
      <origin rpy="0 0 0" xyz="0 0 0.2"/>
      <geometry>
        <!--mesh filename="package://iit-kuka_lwr-ros-pkg/meshes/convex/arm_segment_b_convex.stl"/-->
        <sphere radius="0.07"/>
      </geometry>
    </collision>
    <collision>
      <origin rpy="0 0 0" xyz="0 -0.06 0.0"/>
      <geometry>
        <sphere radius="0.07"/>
      </geometry>
    </collision>
    <collision>
      <origin rpy="-0.291 0 0" xyz="0 -0.03 0.1"/>
      <geometry>
        <cylinder length="0.208" radius="0.07"/>
      </geometry>
    </collision>
  </link>
  <!-- Fourth element of the arm. z-axis -->
  <joint name="kuka_lwr_2_joint" type="revolute">
    <origin rpy="0 0 0" xyz="0 0 0.20"/>
    <axis xyz="0 0 1"/>
    <limit effort="100" lower="-2.96705972839" upper="2.96705972839" velocity="2.23402144255"/>
    <dynamics damping="1.0" friction="10.0"/>
    <parent link="kuka_lwr_2_link"/>
    <child link="kuka_lwr_3_link"/>
  </joint>
  <!-- 			LINK 3 			-->
  <link name="kuka_lwr_3_link">
    <inertial>
      <mass value="2.0"/>
      <origin rpy="0 0 0" xyz="0 0.06 0.130"/>
      <inertia ixx="0.0136666666667" ixy="0" ixz="0" iyy="0.003" iyz="0" izz="0.0118666666667"/>
    </inertial>
    <visual>
      <origin rpy="0 0 0" xyz="0 0 0"/>
      <geometry>
        <mesh filename="package://iit-kuka_lwr-ros-pkg/meshes_arm/arm_segment_a.dae"/>
      </geometry>
      <material name="Orange"/>
    </visual>
    <collision>
      <origin rpy="0 0 0" xyz="0 0 0.0"/>
      <geometry>
        <!--mesh filename="package://iit-kuka_lwr-ros-pkg/meshes/convex/arm_segment_a_convex.stl"/-->
        <sphere radius="0.07"/>
      </geometry>
    </collision>
    <collision>
      <origin rpy="0 0 0" xyz="0 -0.06 0.2"/>
      <geometry>
        <sphere radius="0.07"/>
      </geometry>
    </collision>
    <collision>
      <origin rpy="0.291 0 0" xyz="0 -0.03 0.1"/>
      <geometry>
        <cylinder length="0.208" radius="0.07"/>
      </geometry>
    </collision>
  </link>
  <!-- fifth element of the arm. x-axis -->
  <joint name="kuka_lwr_3_joint" type="revolute">
    <origin rpy="0 0 0" xyz="0 0 0.20"/>
    <axis xyz="0 1 0"/>
    <limit effort="100" lower="-2.09439510239" upper="2.09439510239" velocity="2.23402144255"/>
    <dynamics damping="1.0" friction="10.0"/>
    <parent link="kuka_lwr_3_link"/>
    <child link="kuka_lwr_4_link"/>
  </joint>
  <!-- 			LINK 4 			-->
  <link name="kuka_lwr_4_link">
    <inertial>
      <mass value="2.0"/>
      <origin rpy="0 0 0" xyz="0 -0.06 0.07"/>
      <inertia ixx="0.0136666666667" ixy="0" ixz="0" iyy="0.003" iyz="0" izz="0.0118666666667"/>
    </inertial>
    <visual>
      <origin rpy="0 3.14159265359 3.14159265359" xyz="0 0 0.2"/>
      <geometry>
        <mesh filename="package://iit-kuka_lwr-ros-pkg/meshes_arm/arm_segment_b.dae"/>
      </geometry>
      <material name="Orange"/>
    </visual>
    <collision>
      <origin rpy="0 0 0" xyz="0 0 0.2"/>
      <geometry>
        <!--mesh filename="package://iit-kuka_lwr-ros-pkg/meshes/convex/arm_segment_b_convex.stl"/-->
        <sphere radius="0.07"/>
      </geometry>
    </collision>
    <collision>
      <origin rpy="0 0 0" xyz="0 0.06 0.0"/>
      <geometry>
        <sphere radius="0.07"/>
      </geometry>
    </collision>
    <collision>
      <origin rpy="0.291 0 0" xyz="0 0.03 0.1"/>
      <geometry>
        <cylinder length="0.208" radius="0.07"/>
      </geometry>
    </collision>
  </link>
  <!-- Sixth element of the arm. z-axis -->
  <joint name="kuka_lwr_4_joint" type="revolute">
    <origin rpy="0 0 0" xyz="0 0 0.20"/>
    <axis xyz="0 0 1"/>
    <limit effort="100" lower="-2.96705972839" upper="2.96705972839" velocity="3.56047167407"/>
    <dynamics damping="1.0" friction="10.0"/>
    <parent link="kuka_lwr_4_link"/>
    <child link="kuka_lwr_5_link"/>
  </joint>
  <!-- 			LINK 5 			-->
  <link name="kuka_lwr_5_link">
    <inertial>
      <mass value="2.0"/>
      <origin rpy="0 0 0" xyz="0 0 0.124"/>
      <inertia ixx="0.0126506666667" ixy="0" ixz="0" iyy="0.003" iyz="0" izz="0.0108506666667"/>
    </inertial>
    <visual>
      <origin rpy="0 0 3.14159265359" xyz="0 0 0"/>
      <geometry name="kuka_lwr_arm_5_geom">
        <mesh filename="package://iit-kuka_lwr-ros-pkg/meshes_arm/arm_segment_last.dae"/>
      </geometry>
      <material name="Orange"/>
    </visual>
    <collision>
      <origin rpy="0 0 0" xyz="0 0 0.0"/>
      <geometry>
        <!--mesh filename="package://iit-kuka_lwr-ros-pkg/meshes/convex/arm_segment_last_convex.stl"/-->
        <sphere radius="0.07"/>
      </geometry>
    </collision>
    <collision>
      <origin rpy="0 0 0" xyz="0 0.04 0.19"/>
      <geometry>
        <sphere radius="0.07"/>
      </geometry>
    </collision>
    <collision>
      <origin rpy="-0.207 0 0" xyz="0 0.02 0.095"/>
      <geometry>
        <cylinder length="0.198" radius="0.07"/>
      </geometry>
    </collision>
  </link>
  <!-- Seventh element of the arm. z-axis -->
  <joint name="kuka_lwr_5_joint" type="revolute">
    <origin rpy="0 0 0" xyz="0 0 0.19"/>
    <axis xyz="0 -1 0"/>
    <limit effort="38" lower="-2.09439510239" upper="2.09439510239" velocity="3.21140582367"/>
    <dynamics damping="1.0" friction="10.0"/>
    <parent link="kuka_lwr_5_link"/>
    <child link="kuka_lwr_6_link"/>
  </joint>
  <!-- 			LINK 6 			-->
  <link name="kuka_lwr_6_link">
    <inertial>
      <mass value="0.2"/>
      <origin rpy="0 0 0" xyz="0 0 0.0625"/>
      <inertia ixx="0.000520833333333" ixy="0" ixz="0" iyy="0.000520833333333" iyz="0" izz="0.000520833333333"/>
    </inertial>
    <visual>
      <origin rpy="0 0 3.14159265359" xyz="0 0 0"/>
      <geometry>
        <mesh filename="package://iit-kuka_lwr-ros-pkg/meshes_arm/arm_wrist.dae"/>
      </geometry>
      <material name="Grey"/>
    </visual>
    <collision>
      <origin rpy="0 0 3.14159265359" xyz="0 0 0"/>
      <geometry>
        <mesh filename="package://iit-kuka_lwr-ros-pkg/meshes/convex/arm_wrist_convex.stl"/>
      </geometry>
    </collision>
  </link>
  <!-- Eighth element of the arm. z-axis -->
  <joint name="kuka_lwr_6_joint" type="revolute">
    <origin rpy="0 0 0" xyz="0 0 0.078"/>
    <axis xyz="0 0 1"/>
    <limit effort="38" lower="-2.96705972839" upper="2.96705972839" velocity="3.21140582367"/>
    <dynamics damping="1.0" friction="10.0"/>
    <parent link="kuka_lwr_6_link"/>
    <child link="kuka_lwr_7_link"/>
  </joint>
  <!-- 			LINK 7 			-->
  <link name="kuka_lwr_7_link">
    <inertial>
      <mass value="0.2"/>
      <origin xyz="0 0 0"/>
      <inertia ixx="0.0333333333333" ixy="0" ixz="0" iyy="0.0333333333333" iyz="0" izz="0.0333333333333"/>
    </inertial>
    <visual>
      <origin rpy="0 0 3.14159265359" xyz="0 0 0"/>
      <geometry>
        <mesh filename="package://iit-kuka_lwr-ros-pkg/meshes/link_7.dae"/>
      </geometry>
      <material name="Kuka/DarkGrey"/>
    </visual>
    <collision>
      <origin rpy="0 0 3.14159265359" xyz="0 0 0"/>
      <geometry>
        <cylinder length="0.05" radius="0.04"/>
      </geometry>
    </collision>
  </link>
  <gazebo>
    <!--<plugin filename="libgazebo_ros_control.so" name="gazebo_ros_control">
      <robotNamespace>/iiwa</robotNamespace>
    </plugin>-->
	<plugin name='xbot_plugin_handler' filename='libGazeboXBotPlugin.so'>
    </plugin>
  </gazebo>
  <gazebo reference="kuka_lwr_base_link">
    <gravity>true</gravity>
  </gazebo>
  <gazebo reference="kuka_lwr_1_link">
    <gravity>true</gravity>
  </gazebo>
  <gazebo reference="kuka_lwr_2_link">
    <gravity>true</gravity>
  </gazebo>
  <gazebo reference="kuka_lwr_3_link">
    <gravity>true</gravity>
  </gazebo>
  <gazebo reference="kuka_lwr_4_link">
    <gravity>true</gravity>
  </gazebo>
  <gazebo reference="kuka_lwr_5_link">
    <gravity>true</gravity>
  </gazebo>
  <gazebo reference="kuka_lwr_6_link">
    <gravity>true</gravity>
  </gazebo>
  <gazebo reference="kuka_lwr_7_link">
    <gravity>true</gravity>
  </gazebo>
  <transmission name="kuka_lwr_0_trans">
    <type>transmission_interface/SimpleTransmission</type>
    <joint name="kuka_lwr_0_joint">
      <hardwareInterface>PositionJointInterface</hardwareInterface>
      <hardwareInterface>EffortJointInterface</hardwareInterface>
    </joint>
    <actuator name="kuka_lwr_0_motor">
      <mechanicalReduction>1</mechanicalReduction>
    </actuator>
  </transmission>
  <transmission name="kuka_lwr_1_trans">
    <type>transmission_interface/SimpleTransmission</type>
    <joint name="kuka_lwr_1_joint">
      <hardwareInterface>PositionJointInterface</hardwareInterface>
      <hardwareInterface>EffortJointInterface</hardwareInterface>
    </joint>
    <actuator name="kuka_lwr_1_motor">
      <mechanicalReduction>1</mechanicalReduction>
    </actuator>
  </transmission>
  <transmission name="kuka_lwr_2_trans">
    <type>transmission_interface/SimpleTransmission</type>
    <joint name="kuka_lwr_2_joint">
      <hardwareInterface>PositionJointInterface</hardwareInterface>
      <hardwareInterface>EffortJointInterface</hardwareInterface>
    </joint>
    <actuator name="kuka_lwr_2_motor">
      <mechanicalReduction>1</mechanicalReduction>
    </actuator>
  </transmission>
  <transmission name="kuka_lwr_3_trans">
    <type>transmission_interface/SimpleTransmission</type>
    <joint name="kuka_lwr_3_joint">
      <hardwareInterface>PositionJointInterface</hardwareInterface>
      <hardwareInterface>EffortJointInterface</hardwareInterface>
    </joint>
    <actuator name="kuka_lwr_3_motor">
      <mechanicalReduction>1</mechanicalReduction>
    </actuator>
  </transmission>
  <transmission name="kuka_lwr_4_trans">
    <type>transmission_interface/SimpleTransmission</type>
    <joint name="kuka_lwr_4_joint">
      <hardwareInterface>PositionJointInterface</hardwareInterface>
      <hardwareInterface>EffortJointInterface</hardwareInterface>
    </joint>
    <actuator name="kuka_lwr_4_motor">
      <mechanicalReduction>1</mechanicalReduction>
    </actuator>
  </transmission>
  <transmission name="kuka_lwr_5_trans">
    <type>transmission_interface/SimpleTransmission</type>
    <joint name="kuka_lwr_5_joint">
      <hardwareInterface>PositionJointInterface</hardwareInterface>
      <hardwareInterface>EffortJointInterface</hardwareInterface>
    </joint>
    <actuator name="kuka_lwr_5_motor">
      <mechanicalReduction>1</mechanicalReduction>
    </actuator>
  </transmission>
  <transmission name="kuka_lwr_6_trans">
    <type>transmission_interface/SimpleTransmission</type>
    <joint name="kuka_lwr_6_joint">
      <hardwareInterface>PositionJointInterface</hardwareInterface>
      <hardwareInterface>EffortJointInterface</hardwareInterface>
    </joint>
    <actuator name="kuka_lwr_6_motor">
      <mechanicalReduction>1</mechanicalReduction>
    </actuator>
  </transmission>
</robot>

