<?xml version="1.0" ?>
<!-- =================================================================================== -->
<!-- |    This document was autogenerated by xacro from walkman.urdf.xacro             | -->
<!-- |    EDITING THIS FILE BY HAND IS NOT RECOMMENDED                                 | -->
<!-- =================================================================================== -->
<robot name="walkman" xmlns:xacro="http://ros.org/wiki/xacro">
  <!-- 
  ROS urdf definition of the WALKMAN humanoid robot by Istituto Italiano di Tecnologia
  
  DO NOT INCLUDE THIS FILE DIRECTLY! USE bigman_robot.urdf.xacro INSTEAD!

  Author: Enrico Mingo Hoffman

  Inertial matrix has to be in CoM frame (URDF specs)

  Velocity and effort limits are fake!
-->
  <!-- ************ MODEL CONFIGURATION ************ -->
  <!-- ***********  MODEL COLORS *********** -->
  <material name="grey">
    <color rgba="0.5 0.5 0.5 1"/>
  </material>
  <material name="dark_grey">
    <color rgba="0.3 0.3 0.3 1"/>
  </material>
  <material name="blue">
    <color rgba="0.0 0.2 0.3 1"/>
  </material>
  <!-- ************ WALKMAN BASE ************** -->
  <!-- 
  ROS urdf definition of the WALK-MAN humanoid robot by Istituto Italiano di Tecnologia
  
  DO NOT INCLUDE THIS FILE DIRECTLY! USE bigman_robot.urdf.xacro INSTEAD!

  Author: Enrico Mingo Hoffman

  Inertial matrix has to be in CoM frame (URDF specs)

-->
  <!--
The coordinate frame called base_link is rigidly attached to the robot root body. It is recommended to choose the robot waist as its root body. The base_link can be attached to the root in any arbitrary position or orientation; for every hardware platform there will be a different place on the base that provides an obvious point of reference. Note that REP 103 [1] specifies a preferred orientation for frames. -->
  <link name="base_link"/>
  <!-- Here some masses are missing! -->
  <link name="Waist">
    <inertial>
      <origin rpy="0.0 0.0 0.0" xyz="0.027038986 -5.1554922e-06 -0.064188178"/>
      <mass value="2.9259094"/>
      <inertia ixx="0.02571361" ixy="9.5008024e-06" ixz="0.0043519496" iyy="0.02494919" iyz="4.5439311e-06" izz="0.02492012"/>
    </inertial>
    <visual>
      <origin rpy="0 0 0" xyz="0 0 0"/>
      <geometry name="Waist_visual">
        <mesh filename="package://walkman_urdf/meshes/Waist.STL" scale="0.001 0.001 0.001"/>
      </geometry>
      <material name="grey"/>
    </visual>
    <collision>
      <origin rpy="0 0 0" xyz="0 0 0"/>
      <geometry name="Waist_collision">
        <mesh filename="package://walkman_urdf/meshes/simple/Waist.STL" scale="0.001 0.001 0.001"/>
      </geometry>
    </collision>
  </link>
  <joint name="base_joint" type="fixed">
    <parent link="base_link"/>
    <child link="Waist"/>
    <origin rpy="0 0 0" xyz="0 0 0"/>
  </joint>
  <!-- LINKS -->
  <!-- ********************RIGHT LEG******************** -->
  <link name="RHipMot">
    <inertial>
      <origin rpy="0 0 0" xyz="-0.10348188 -0.10919813 -0.064924056"/>
      <mass value="3.7958197"/>
      <inertia ixx="0.015639017" ixy="0.0018504661" ixz="0.0023907793" iyy="0.023519749" iyz="-0.0023303162" izz="0.020953643"/>
    </inertial>
    <visual>
      <origin rpy="0 0 0" xyz="0 0 0"/>
      <geometry name="RHipMot_visual">
        <mesh filename="package://walkman_urdf/meshes/HipRoll.STL" scale="0.001 0.001 0.001"/>
      </geometry>
      <material name="dark_grey"/>
    </visual>
    <collision>
      <origin rpy="0 0 0" xyz="0 0 0"/>
      <geometry name="RHipMot_collision">
        <mesh filename="package://walkman_urdf/meshes/simple/HipRoll.STL" scale="0.001 0.001 0.001"/>
      </geometry>
    </collision>
  </link>
  <link name="RThighUpLeg">
    <inertial>
      <origin rpy="0 0 0" xyz="-0.0052929709 -0.022561833 0.0056701669"/>
      <mass value="3.2402068"/>
      <inertia ixx="0.010102097" ixy="0.00010858487" ixz="0.00025291395" iyy="0.0067147" iyz="8.3447072e-05" izz="0.01048513"/>
    </inertial>
    <visual>
      <origin rpy="0 0 0" xyz="0 0 0"/>
      <geometry name="RThighUpLeg_visual">
        <mesh filename="package://walkman_urdf/meshes/HipYaw.STL" scale="0.001 0.001 0.001"/>
      </geometry>
      <material name="dark_grey"/>
    </visual>
    <collision>
      <origin rpy="0 0 0" xyz="0 0 0"/>
      <geometry name="RThighUpLeg_collision">
        <mesh filename="package://walkman_urdf/meshes/simple/HipYaw.STL" scale="0.001 0.001 0.001"/>
      </geometry>
    </collision>
  </link>
  <link name="RThighLowLeg">
    <inertial>
      <origin rpy="0 0 0" xyz="0.037746286 -0.028539939 -0.19310133"/>
      <mass value="5.0950736"/>
      <inertia ixx="0.051607858" ixy="0.0022253472" ixz="0.002452979" iyy="0.044349153" iyz="-0.0041006942" izz="0.023374453"/>
    </inertial>
    <visual>
      <origin rpy="0 0 0" xyz="0 0 0"/>
      <geometry name="RThighLowLeg_visual">
        <mesh filename="package://walkman_urdf/meshes/HipPitch.STL" scale="0.001 0.001 0.001"/>
      </geometry>
      <material name="grey"/>
    </visual>
    <collision>
      <origin rpy="0 0 0" xyz="0 0 0"/>
      <geometry name="RThighLowLeg_collision">
        <mesh filename="package://walkman_urdf/meshes/simple/HipPitch.STL" scale="0.001 0.001 0.001"/>
      </geometry>
    </collision>
  </link>
  <link name="RLowLeg">
    <inertial>
      <origin rpy="0 0 0" xyz="-0.0050828668 0.0037732093 -0.072605017"/>
      <mass value="5.6495309"/>
      <inertia ixx="0.10535542" ixy="-0.00058199221" ixz="0.0016743598" iyy="0.097857796" iyz="-0.0033770181" izz="0.020854086"/>
    </inertial>
    <visual>
      <origin rpy="0 0 0" xyz="0 0 0"/>
      <geometry name="RLowLeg_visual">
        <mesh filename="package://walkman_urdf/meshes/KneePitchCalf.STL" scale="0.001 0.001 0.001"/>
      </geometry>
      <material name="dark_grey"/>
    </visual>
    <collision>
      <origin rpy="0 0 0" xyz="0 0 0"/>
      <geometry name="RLowLeg_collision">
        <mesh filename="package://walkman_urdf/meshes/simple/KneePitchCalf.STL" scale="0.001 0.001 0.001"/>
      </geometry>
    </collision>
  </link>
  <link name="RFootmot">
    <inertial>
      <origin rpy="0 0 0" xyz="-0.022024173 0.0025677238 0.00094588455"/>
      <mass value="3.2844159"/>
      <inertia ixx="0.0075550679" ixy="0.00067488292" ixz="5.8332889e-05" iyy="0.011241163" iyz="-0.00014552081" izz="0.013391865"/>
    </inertial>
    <visual>
      <origin rpy="0 0 0" xyz="0 0 0"/>
      <geometry name="RFootmot_visual">
        <mesh filename="package://walkman_urdf/meshes/AnklePitch.STL" scale="0.001 0.001 0.001"/>
      </geometry>
      <material name="dark_grey"/>
    </visual>
    <collision>
      <origin rpy="0 0 0" xyz="0 0 0"/>
      <geometry name="RFootmot_collision">
        <mesh filename="package://walkman_urdf/meshes/simple/AnklePitch.STL" scale="0.001 0.001 0.001"/>
      </geometry>
    </collision>
  </link>
  <link name="RFoot">
    <inertial>
      <origin rpy="0 0 0" xyz="-0.00653584 -0.00479384 -0.10180375"/>
      <mass value="3.42638110"/>
      <inertia ixx="0.01032886" ixy="-0.00016407" ixz="-0.00201294" iyy="0.02854025" iyz="0.00046315" izz="0.02799499"/>
    </inertial>
    <visual>
      <origin rpy="0 0 0" xyz="0 0 0"/>
      <geometry name="RFoot_visual">
        <mesh filename="package://walkman_urdf/meshes/Foot.STL" scale="0.001 0.001 0.001"/>
      </geometry>
      <material name="dark_grey"/>
    </visual>
    <collision>
      <origin rpy="0 0 0" xyz="0.005 -0.01 -0.1359"/>
      <geometry>
        <box size="0.32 0.16 0.015"/>
      </geometry>
    </collision>
  </link>
  <!-- ********************LEFT LEG******************** -->
  <link name="LHipMot">
    <inertial>
      <origin rpy="0 0 0" xyz="-0.10348188 0.10919813 -0.064924056"/>
      <mass value="3.7958197"/>
      <inertia ixx="0.015639017" ixy="-0.0018504661" ixz="0.0023907793" iyy="0.023519749" iyz="0.0023303162" izz="0.020953643"/>
    </inertial>
    <visual>
      <origin rpy="0 0 0" xyz="0 0 0"/>
      <geometry name="LHipMot_visual">
        <mesh filename="package://walkman_urdf/meshes/HipRoll.STL" scale="0.001 -0.001 0.001"/>
      </geometry>
      <material name="dark_grey"/>
    </visual>
    <collision>
      <origin rpy="0 0 0" xyz="0 0 0"/>
      <geometry name="LHipMot_collision">
        <mesh filename="package://walkman_urdf/meshes/simple/HipRoll.STL" scale="0.001 -0.001 0.001"/>
      </geometry>
    </collision>
  </link>
  <link name="LThighUpLeg">
    <inertial>
      <origin rpy="0 0 0" xyz="-0.0052929709 0.022561833 0.0056701669"/>
      <mass value="3.2402068"/>
      <inertia ixx="0.010102097" ixy="-0.00010858487" ixz="0.00025291395" iyy="0.0067147" iyz="-8.3447072e-05" izz="0.01048513"/>
    </inertial>
    <visual>
      <origin rpy="0 0 0" xyz="0 0 0"/>
      <geometry name="LThighUpLeg_visual">
        <mesh filename="package://walkman_urdf/meshes/HipYaw.STL" scale="0.001 -0.001 0.001"/>
      </geometry>
      <material name="dark_grey"/>
    </visual>
    <collision>
      <origin rpy="0 0 0" xyz="0 0 0"/>
      <geometry name="LThighUpLeg_collision">
        <mesh filename="package://walkman_urdf/meshes/simple/HipYaw.STL" scale="0.001 -0.001 0.001"/>
      </geometry>
    </collision>
  </link>
  <link name="LThighLowLeg">
    <inertial>
      <origin rpy="0 0 0" xyz="0.037746286 0.028539939 -0.19310133"/>
      <mass value="5.0950736"/>
      <inertia ixx="0.051607858" ixy="-0.0022253472" ixz="0.002452979" iyy="0.044349153" iyz="0.0041006942" izz="0.023374453"/>
    </inertial>
    <visual>
      <origin rpy="0 0 0" xyz="0 0 0"/>
      <geometry name="LThighLowLeg_visual">
        <mesh filename="package://walkman_urdf/meshes/HipPitch.STL" scale="0.001 -0.001 0.001"/>
      </geometry>
      <material name="grey"/>
    </visual>
    <collision>
      <origin rpy="0 0 0" xyz="0 0 0"/>
      <geometry name="LThighLowLeg_collision">
        <mesh filename="package://walkman_urdf/meshes/simple/HipPitch.STL" scale="0.001 -0.001 0.001"/>
      </geometry>
    </collision>
  </link>
  <link name="LLowLeg">
    <inertial>
      <origin rpy="0 0 0" xyz="-0.0050828668 -0.0037732093 -0.072605017"/>
      <mass value="5.6495309"/>
      <inertia ixx="0.10535542" ixy="0.00058199221" ixz="0.0016743598" iyy="0.097857796" iyz="0.0033770181" izz="0.020854086"/>
    </inertial>
    <visual>
      <origin rpy="0 0 0" xyz="0 0 0"/>
      <geometry name="LLowLeg_visual">
        <mesh filename="package://walkman_urdf/meshes/KneePitchCalf.STL" scale="0.001 -0.001 0.001"/>
      </geometry>
      <material name="dark_grey"/>
    </visual>
    <collision>
      <origin rpy="0 0 0" xyz="0 0 0"/>
      <geometry name="LLowLeg_collision">
        <mesh filename="package://walkman_urdf/meshes/simple/KneePitchCalf.STL" scale="0.001 -0.001 0.001"/>
      </geometry>
    </collision>
  </link>
  <link name="LFootmot">
    <inertial>
      <origin rpy="0 0 0" xyz="-0.022024173 -0.0025677238 0.00094588455"/>
      <mass value="3.2844159"/>
      <inertia ixx="0.0075550679" ixy="-0.00067488292" ixz="5.8332889e-05" iyy="0.011241163" iyz="0.00014552081" izz="0.013391865"/>
    </inertial>
    <visual>
      <origin rpy="0 0 0" xyz="0 0 0"/>
      <geometry name="LFootmot_visual">
        <mesh filename="package://walkman_urdf/meshes/AnklePitch.STL" scale="0.001 -0.001 0.001"/>
      </geometry>
      <material name="dark_grey"/>
    </visual>
    <collision>
      <origin rpy="0 0 0" xyz="0 0 0"/>
      <geometry name="LFootmot_collision">
        <mesh filename="package://walkman_urdf/meshes/simple/AnklePitch.STL" scale="0.001 -0.001 0.001"/>
      </geometry>
    </collision>
  </link>
  <link name="LFoot">
    <inertial>
      <origin rpy="0 0 0" xyz="-0.00653584 0.00479384 -0.10180375"/>
      <mass value="3.42638110"/>
      <inertia ixx="0.01032886" ixy="0.00016407" ixz="-0.00201294" iyy="0.02854025" iyz="-0.00046315" izz="0.02799499"/>
    </inertial>
    <visual>
      <origin rpy="0 0 0" xyz="0 0 0"/>
      <geometry name="LFoot_visual">
        <mesh filename="package://walkman_urdf/meshes/Foot.STL" scale="0.001 -0.001 0.001"/>
      </geometry>
      <material name="dark_grey"/>
    </visual>
    <collision>
      <origin rpy="0 0 0" xyz="0.005 0.01 -0.1359"/>
      <geometry>
        <box size="0.32 0.16 0.015"/>
      </geometry>
    </collision>
  </link>
  <!-- JOINTS -->
  <!-- ********************RIGHT LEG******************** -->
  <joint name="RHipLat" type="revolute">
    <parent link="Waist"/>
    <child link="RHipMot"/>
    <origin rpy="0 0 0" xyz="0.1569 -0.06 -0.108"/>
    <axis xyz="1 0 0"/>
    <limit effort="400" lower="-0.87222" upper="0.697778" velocity="6.283"/>
    <dynamics damping="3.0" friction="0"/>
  </joint>
  <joint name="RHipYaw" type="revolute">
    <parent link="RHipMot"/>
    <child link="RThighUpLeg"/>
    <origin rpy="0 0 0" xyz="-0.0889 -0.121032 -0.217872"/>
    <axis xyz="0 0 1"/>
    <limit effort="140" lower="-1.57" upper="0.872222" velocity="6.283"/>
    <dynamics damping="3.0" friction="0"/>
  </joint>
  <joint name="RHipSag" type="revolute">
    <parent link="RThighUpLeg"/>
    <child link="RThighLowLeg"/>
    <origin rpy="0 0 0" xyz="0.0 0.0 0.0"/>
    <axis xyz="0 1 0"/>
    <limit effort="400" lower="-2.09333" upper="1.046667" velocity="6.283"/>
    <dynamics damping="3.0" friction="0"/>
  </joint>
  <joint name="RKneeSag" type="revolute">
    <parent link="RThighLowLeg"/>
    <child link="RLowLeg"/>
    <origin rpy="0 0 0" xyz="0.0 0.0 -0.356"/>
    <axis xyz="0 1 0"/>
    <limit effort="400" lower="0.0" upper="2.442222" velocity="6.283"/>
    <dynamics damping="3.0" friction="0"/>
  </joint>
  <joint name="RAnkSag" type="revolute">
    <parent link="RLowLeg"/>
    <child link="RFootmot"/>
    <origin rpy="0 0 0" xyz="0.0 0.0 -0.4"/>
    <axis xyz="0 1 0"/>
    <limit effort="330" lower="-1.39556" upper="0.697778" velocity="6.283"/>
    <dynamics damping="3.0" friction="0"/>
  </joint>
  <joint name="RAnkLat" type="revolute">
    <parent link="RFootmot"/>
    <child link="RFoot"/>
    <origin rpy="0 0 0" xyz="0.0 0.0 0.0"/>
    <axis xyz="1 0 0"/>
    <limit effort="210" lower="-0.785" upper="0.785" velocity="6.283"/>
    <dynamics damping="3.0" friction="0"/>
  </joint>
  <!-- ********************LEFT LEG******************** -->
  <joint name="LHipLat" type="revolute">
    <parent link="Waist"/>
    <child link="LHipMot"/>
    <origin rpy="0 0 0" xyz="0.1569 0.06 -0.108"/>
    <axis xyz="1 0 0"/>
    <limit effort="400" lower="-0.697778" upper="0.87222" velocity="6.283"/>
    <dynamics damping="3.0" friction="0"/>
  </joint>
  <joint name="LHipYaw" type="revolute">
    <parent link="LHipMot"/>
    <child link="LThighUpLeg"/>
    <origin rpy="0 0 0" xyz="-0.0889 0.121032 -0.217872"/>
    <axis xyz="0 0 1"/>
    <limit effort="140" lower="-0.872222" upper="1.57" velocity="6.283"/>
    <dynamics damping="3.0" friction="0"/>
  </joint>
  <joint name="LHipSag" type="revolute">
    <parent link="LThighUpLeg"/>
    <child link="LThighLowLeg"/>
    <origin rpy="0 0 0" xyz="0.0 0.0 0.0"/>
    <axis xyz="0 1 0"/>
    <limit effort="400" lower="-2.09333" upper="1.046667" velocity="6.283"/>
    <dynamics damping="3.0" friction="0"/>
  </joint>
  <joint name="LKneeSag" type="revolute">
    <parent link="LThighLowLeg"/>
    <child link="LLowLeg"/>
    <origin rpy="0 0 0" xyz="0.0 0.0 -0.356"/>
    <axis xyz="0 1 0"/>
    <limit effort="400" lower="0.0" upper="2.442222" velocity="6.283"/>
    <dynamics damping="3.0" friction="0"/>
  </joint>
  <joint name="LAnkSag" type="revolute">
    <parent link="LLowLeg"/>
    <child link="LFootmot"/>
    <origin rpy="0 0 0" xyz="0.0 0.0 -0.4"/>
    <axis xyz="0 1 0"/>
    <limit effort="330" lower="-1.39556" upper="0.697778" velocity="6.283"/>
    <dynamics damping="3.0" friction="0"/>
  </joint>
  <joint name="LAnkLat" type="revolute">
    <parent link="LFootmot"/>
    <child link="LFoot"/>
    <origin rpy="0 0 0" xyz="0.0 0.0 0.0"/>
    <axis xyz="1 0 0"/>
    <limit effort="210" lower="-0.785" upper="0.785" velocity="6.283"/>
    <dynamics damping="3.0" friction="0"/>
  </joint>
  <link name="l_ankle"/>
  <link name="r_ankle"/>
  <link name="l_sole"/>
  <link name="r_sole"/>
  <joint name="l_ankle_joint" type="fixed">
    <parent link="LFoot"/>
    <child link="l_ankle"/>
    <origin rpy="0 0 0" xyz="0 0 0"/>
  </joint>
  <joint name="r_ankle_joint" type="fixed">
    <parent link="RFoot"/>
    <child link="r_ankle"/>
    <origin rpy="0 0 0" xyz="0 0 0"/>
  </joint>
  <joint name="l_sole_joint" type="fixed">
    <parent link="LFoot"/>
    <child link="l_sole"/>
    <origin rpy="0 0 0" xyz="0 0 -0.1435"/>
  </joint>
  <joint name="r_sole_joint" type="fixed">
    <parent link="RFoot"/>
    <child link="r_sole"/>
    <origin rpy="0 0 0" xyz="0 0 -0.1435"/>
  </joint>
  <!-- macro for reference frames in foot -->
  <!-- macro for one reference frame in foot -->
  <link name="l_foot_upper_right_link"/>
  <joint name="l_foot_upper_right_joint" type="fixed">
    <origin rpy="0 0 0" xyz="0.16 -0.07 0"/>
    <parent link="l_sole"/>
    <child link="l_foot_upper_right_link"/>
  </joint>
  <!-- macro for one reference frame in foot -->
  <link name="l_foot_upper_left_link"/>
  <joint name="l_foot_upper_left_joint" type="fixed">
    <origin rpy="0 0 0" xyz="0.16 0.09 0"/>
    <parent link="l_sole"/>
    <child link="l_foot_upper_left_link"/>
  </joint>
  <!-- macro for one reference frame in foot -->
  <link name="l_foot_lower_right_link"/>
  <joint name="l_foot_lower_right_joint" type="fixed">
    <origin rpy="0 0 0" xyz="-0.16 -0.07 0"/>
    <parent link="l_sole"/>
    <child link="l_foot_lower_right_link"/>
  </joint>
  <!-- macro for one reference frame in foot -->
  <link name="l_foot_lower_left_link"/>
  <joint name="l_foot_lower_left_joint" type="fixed">
    <origin rpy="0 0 0" xyz="-0.16 0.09 0"/>
    <parent link="l_sole"/>
    <child link="l_foot_lower_left_link"/>
  </joint>
  <!-- macro for reference frames in foot -->
  <!-- macro for one reference frame in foot -->
  <link name="r_foot_upper_right_link"/>
  <joint name="r_foot_upper_right_joint" type="fixed">
    <origin rpy="0 0 0" xyz="0.16 0.07 0"/>
    <parent link="r_sole"/>
    <child link="r_foot_upper_right_link"/>
  </joint>
  <!-- macro for one reference frame in foot -->
  <link name="r_foot_upper_left_link"/>
  <joint name="r_foot_upper_left_joint" type="fixed">
    <origin rpy="0 0 0" xyz="0.16 -0.09 0"/>
    <parent link="r_sole"/>
    <child link="r_foot_upper_left_link"/>
  </joint>
  <!-- macro for one reference frame in foot -->
  <link name="r_foot_lower_right_link"/>
  <joint name="r_foot_lower_right_joint" type="fixed">
    <origin rpy="0 0 0" xyz="-0.16 0.07 0"/>
    <parent link="r_sole"/>
    <child link="r_foot_lower_right_link"/>
  </joint>
  <!-- macro for one reference frame in foot -->
  <link name="r_foot_lower_left_link"/>
  <joint name="r_foot_lower_left_joint" type="fixed">
    <origin rpy="0 0 0" xyz="-0.16 -0.09 0"/>
    <parent link="r_sole"/>
    <child link="r_foot_lower_left_link"/>
  </joint>
  <!-- LINKS -->
  <!-- This links are defined in order to be compliant with http://www.ros.org/reps/rep-0120.html#coordinate-frames
and to define the end effectors of the robot-->
  <!-- The coordinate frame called torso is attached to the lowest body of the model which is a parent of l_gripper, r_gripper and gaze. -->
  <link name="DWL">
    <inertial>
      <origin rpy="0 0 0" xyz="-0.013438629 -2.4995993e-05 0.073562799"/>
      <mass value="2.4309068"/>
      <inertia ixx="0.016702798" ixy="3.5908153e-05" ixz="-0.0041709274" iyy="0.019440925" iyz="1.1578036e-05" izz="0.0057721068"/>
    </inertial>
    <visual>
      <origin rpy="0 0 0" xyz="0.0 0.0 0.0"/>
      <geometry name="DWL_visual">
        <mesh filename="package://walkman_urdf/meshes/TorsoRoll.STL" scale="0.001 0.001 0.001"/>
      </geometry>
      <material name="dark_grey"/>
    </visual>
    <collision>
      <origin rpy="0 0 0" xyz="0.0 0.0 0.0"/>
      <geometry name="DWL_collision">
        <mesh filename="package://walkman_urdf/meshes/simple/TorsoRoll.STL" scale="0.001 0.001 0.001"/>
      </geometry>
    </collision>
  </link>
  <link name="DWYTorso">
    <inertial>
      <origin rpy="0 0 0" xyz="-0.059646212 0.0014305062 0.042741527"/>
      <mass value="1.2512295e+01"/>
      <inertia ixx="0.21021617" ixy="-0.00015527214" ixz="-0.050216602" iyy="0.19982996" iyz="-0.00029204792" izz="0.14025094"/>
    </inertial>
    <visual>
      <origin rpy="0 0 0" xyz="0.0 0.0 0.0"/>
      <geometry name="DWYTorso_visual">
        <mesh filename="package://walkman_urdf/meshes/Chest.STL" scale="0.001 0.001 0.001"/>
      </geometry>
      <material name="blue"/>
    </visual>
    <collision>
      <origin rpy="0 0 0" xyz="0.0 0.0 0.0"/>
      <geometry name="DWYTorso_collision">
        <mesh filename="package://walkman_urdf/meshes/simple/Chest.STL" scale="0.001 0.001 0.001"/>
      </geometry>
    </collision>
  </link>
  <!--link name="torso"/-->
  <!-- JOINTS -->
  <!--joint name="torso_joint" type="fixed">
    <parent link="DWYTorso"/>
    <child link="torso"/>
    <origin xyz="0.0 0 0.0" rpy="0 0 0" /> 
</joint-->
  <joint name="WaistLat" type="revolute">
    <parent link="Waist"/>
    <child link="DWL"/>
    <origin rpy="0 0 0" xyz="0.0596 0 0.0"/>
    <axis xyz="1 0 0"/>
    <limit effort="120" lower="-0.610865238196" upper="0.610865238196" velocity="6.283"/>
    <dynamics damping="3.0" friction="0"/>
  </joint>
  <joint name="WaistYaw" type="revolute">
    <parent link="DWL"/>
    <child link="DWYTorso"/>
    <origin rpy="0 0 0" xyz="0.0088 0 0.22215"/>
    <axis xyz="0 0 1"/>
    <limit effort="120" lower="-1.74532925199" upper="1.74532925199" velocity="6.283"/>
    <dynamics damping="3.0" friction="0"/>
  </joint>
  <!-- LINKS -->
  <link name="NeckYaw">
    <inertial>
      <origin rpy="0 0 0" xyz="0.00017665124 -0.00056962982 0.009696191 "/>
      <mass value="5.9544662e-01"/>
      <inertia ixx="0.00044402452" ixy="-4.7573996e-08" ixz="1.2703055e-07" iyy="0.00036958221" iyz="5.6524326e-06" izz="0.00027123782"/>
    </inertial>
    <visual>
      <origin rpy="0 0 0" xyz="0.0 0.0 0.0"/>
      <geometry name="NeckYaw_visual">
        <mesh filename="package://walkman_urdf/meshes/NeckYaw.STL" scale="0.001 0.001 0.001"/>
      </geometry>
      <material name="grey"/>
    </visual>
    <collision>
      <origin rpy="0 0 0" xyz="0.0 0.0 0.0"/>
      <geometry name="NeckYaw_collision">
        <mesh filename="package://walkman_urdf/meshes/simple/NeckYaw.STL" scale="0.001 0.001 0.001"/>
      </geometry>
    </collision>
  </link>
  <link name="NeckPitch">
    <inertial>
      <origin rpy="0 0 0" xyz="0.0065724785 -0.034569915 0.11402826"/>
      <mass value="3.1388490"/>
      <inertia ixx="0.022067171" ixy="-3.2510922e-05" ixz="-0.001205899" iyy="0.019140289" iyz="-9.6672078e-05" izz="0.021334662"/>
    </inertial>
    <visual>
      <origin rpy="0 0 0" xyz="0.0 0.0 0.0"/>
      <geometry name="NeckPitch_visual">
        <mesh filename="package://walkman_urdf/meshes/NeckPitch.STL" scale="0.001 0.001 0.001"/>
      </geometry>
      <material name="grey"/>
    </visual>
    <collision>
      <origin rpy="0 0 0" xyz="0.0 0.0 0.0"/>
      <geometry name="NeckPitch_collision">
        <mesh filename="package://walkman_urdf/meshes/simple/NeckPitch.STL" scale="0.001 0.001 0.001"/>
      </geometry>
    </collision>
  </link>
  <!-- JOINTS -->
  <joint name="NeckYawj" type="revolute">
    <parent link="DWYTorso"/>
    <child link="NeckYaw"/>
    <origin rpy="0 0 0" xyz="0.016 0 0.238292"/>
    <axis xyz="0 0 1"/>
    <limit effort="120" lower="-0.610865238196" upper="0.610865238196" velocity="6.283"/>
    <dynamics damping="3.0" friction="0"/>
  </joint>
  <joint name="NeckPitchj" type="revolute">
    <parent link="NeckYaw"/>
    <child link="NeckPitch"/>
    <origin rpy="0 0 0" xyz="0 0.03425 0.027"/>
    <axis xyz="0 1 0"/>
    <limit effort="120" lower="-0.261799387798" upper="1.04719755119" velocity="6.283"/>
    <dynamics damping="3.0" friction="0"/>
  </joint>
  <!--xacro:include filename="$(find bigman_urdf)/urdf/parts/arms.urdf.xacro" /-->
  <link name="world"/>
  <joint name="reference" type="floating">
    <origin xyz="0.0 0.0 0.0"/>
    <parent link="world"/>
    <child link="base_link"/>
  </joint>
  <link name="l_leg_ft"/>
  <link name="r_leg_ft"/>
  <joint name="l_leg_ft_joint" type="fixed">
    <parent link="LFoot"/>
    <child link="l_leg_ft"/>
    <origin rpy="0 0 0" xyz="0.005 0 -0.107"/>
  </joint>
  <joint name="r_leg_ft_joint" type="fixed">
    <parent link="RFoot"/>
    <child link="r_leg_ft"/>
    <origin rpy="0 0 0" xyz="0.005 0 -0.107"/>
  </joint>
  <!--
	<link name="l_arm_ft"/>
	<link name="r_arm_ft"/>

	<joint name="l_arm_ft_joint" type="fixed">
	    <parent link="LWrMot3"/>
	    <child link="l_arm_ft"/>
	    <origin xyz="0 0 -0.0565" rpy="0 0 0" /> 
	</joint>

	<joint name="r_arm_ft_joint" type="fixed">
	    <parent link="RWrMot3"/>
	    <child link="r_arm_ft"/>
	    <origin xyz="0 0 -0.0565" rpy="0 0 0" /> 
	</joint>



	<link name="l_wrist"/>
	<link name="r_wrist"/>

	<xacro:include filename="$(find bigman_urdf)/urdf/parts/forearms.urdf.xacro" />
       <xacro:if value="${BIGMAN_ADD_RAISING_SUPPORT}">
	       <xacro:include filename="$(find bigman_urdf)/urdf/parts/forearm_reference_frame.urdf.xacro" />
       </xacro:if>

	<xacro:include filename="$(find bigman_urdf)/urdf/parts/soft_hand.urdf.xacro" />

		


<xacro:include filename="$(find bigman_urdf)/urdf/sensors/imu.urdf.xacro"/>
-->
</robot>

