<?xml version="1.0" ?>
<!-- =================================================================================== -->
<!-- |    This document was autogenerated by xacro from walkman.urdf.xacro             | -->
<!-- |    EDITING THIS FILE BY HAND IS NOT RECOMMENDED                                 | -->
<!-- =================================================================================== -->
<robot name="walkman" xmlns:xacro="http://ros.org/wiki/xacro">
  <!-- 
  ROS urdf definition of the WALKMAN humanoid robot by Istituto Italiano di Tecnologia
  
  DO NOT INCLUDE THIS FILE DIRECTLY! USE bigman_robot.urdf.xacro INSTEAD!

  Author: Enrico Mingo Hoffman

  Inertial matrix has to be in CoM frame (URDF specs)

  Velocity and effort limits are fake!
-->
  <!-- ************ MODEL CONFIGURATION ************ -->
  <!-- ***********  MODEL COLORS *********** -->
  <material name="grey">
    <color rgba="0.5 0.5 0.5 1"/>
  </material>
  <material name="dark_grey">
    <color rgba="0.3 0.3 0.3 1"/>
  </material>
  <material name="blue">
    <color rgba="0.0 0.2 0.3 1"/>
  </material>
  <!-- ************ WALKMAN BASE ************** -->
  <!-- 
  ROS urdf definition of the WALK-MAN humanoid robot by Istituto Italiano di Tecnologia
  
  DO NOT INCLUDE THIS FILE DIRECTLY! USE bigman_robot.urdf.xacro INSTEAD!

  Author: Enrico Mingo Hoffman

  Inertial matrix has to be in CoM frame (URDF specs)

-->
  <!--
The coordinate frame called base_link is rigidly attached to the robot root body. It is recommended to choose the robot waist as its root body. The base_link can be attached to the root in any arbitrary position or orientation; for every hardware platform there will be a different place on the base that provides an obvious point of reference. Note that REP 103 [1] specifies a preferred orientation for frames. -->
  <link name="base_link"/>
  <!-- Here some masses are missing! -->
  <link name="Waist">
    <inertial>
      <origin rpy="0.0 0.0 0.0" xyz="0.027038986 -5.1554922e-06 -0.064188178"/>
      <mass value="2.9259094"/>
      <inertia ixx="0.02571361" ixy="9.5008024e-06" ixz="0.0043519496" iyy="0.02494919" iyz="4.5439311e-06" izz="0.02492012"/>
    </inertial>
    <visual>
      <origin rpy="0 0 0" xyz="0 0 0"/>
      <geometry name="Waist_visual">
        <mesh filename="package://walkman_urdf/meshes/Waist.STL" scale="0.001 0.001 0.001"/>
      </geometry>
      <material name="grey"/>
    </visual>
    <collision>
      <origin rpy="0 0 0" xyz="0 0 0"/>
      <geometry name="Waist_collision">
        <mesh filename="package://walkman_urdf/meshes/simple/Waist.STL" scale="0.001 0.001 0.001"/>
      </geometry>
    </collision>
  </link>
  <joint name="base_joint" type="fixed">
    <parent link="base_link"/>
    <child link="Waist"/>
    <origin rpy="0 0 0" xyz="0 0 0"/>
  </joint>
  <!-- LINKS -->
  <!-- ********************RIGHT LEG******************** -->
  <link name="RHipMot">
    <inertial>
      <origin rpy="0 0 0" xyz="-0.10348188 -0.10919813 -0.064924056"/>
      <mass value="3.7958197"/>
      <inertia ixx="0.015639017" ixy="0.0018504661" ixz="0.0023907793" iyy="0.023519749" iyz="-0.0023303162" izz="0.020953643"/>
    </inertial>
    <visual>
      <origin rpy="0 0 0" xyz="0 0 0"/>
      <geometry name="RHipMot_visual">
        <mesh filename="package://walkman_urdf/meshes/HipRoll.STL" scale="0.001 0.001 0.001"/>
      </geometry>
      <material name="dark_grey"/>
    </visual>
    <collision>
      <origin rpy="0 0 0" xyz="0 0 0"/>
      <geometry name="RHipMot_collision">
        <mesh filename="package://walkman_urdf/meshes/simple/HipRoll.STL" scale="0.001 0.001 0.001"/>
      </geometry>
    </collision>
  </link>
  <link name="RThighUpLeg">
    <inertial>
      <origin rpy="0 0 0" xyz="-0.0052929709 -0.022561833 0.0056701669"/>
      <mass value="3.2402068"/>
      <inertia ixx="0.010102097" ixy="0.00010858487" ixz="0.00025291395" iyy="0.0067147" iyz="8.3447072e-05" izz="0.01048513"/>
    </inertial>
    <visual>
      <origin rpy="0 0 0" xyz="0 0 0"/>
      <geometry name="RThighUpLeg_visual">
        <mesh filename="package://walkman_urdf/meshes/HipYaw.STL" scale="0.001 0.001 0.001"/>
      </geometry>
      <material name="dark_grey"/>
    </visual>
    <collision>
      <origin rpy="0 0 0" xyz="0 0 0"/>
      <geometry name="RThighUpLeg_collision">
        <mesh filename="package://walkman_urdf/meshes/simple/HipYaw.STL" scale="0.001 0.001 0.001"/>
      </geometry>
    </collision>
  </link>
  <link name="RThighLowLeg">
    <inertial>
      <origin rpy="0 0 0" xyz="0.037746286 -0.028539939 -0.19310133"/>
      <mass value="5.0950736"/>
      <inertia ixx="0.051607858" ixy="0.0022253472" ixz="0.002452979" iyy="0.044349153" iyz="-0.0041006942" izz="0.023374453"/>
    </inertial>
    <visual>
      <origin rpy="0 0 0" xyz="0 0 0"/>
      <geometry name="RThighLowLeg_visual">
        <mesh filename="package://walkman_urdf/meshes/HipPitch.STL" scale="0.001 0.001 0.001"/>
      </geometry>
      <material name="grey"/>
    </visual>
    <collision>
      <origin rpy="0 0 0" xyz="0 0 0"/>
      <geometry name="RThighLowLeg_collision">
        <mesh filename="package://walkman_urdf/meshes/simple/HipPitch.STL" scale="0.001 0.001 0.001"/>
      </geometry>
    </collision>
  </link>
  <link name="RLowLeg">
    <inertial>
      <origin rpy="0 0 0" xyz="-0.0050828668 0.0037732093 -0.072605017"/>
      <mass value="5.6495309"/>
      <inertia ixx="0.10535542" ixy="-0.00058199221" ixz="0.0016743598" iyy="0.097857796" iyz="-0.0033770181" izz="0.020854086"/>
    </inertial>
    <visual>
      <origin rpy="0 0 0" xyz="0 0 0"/>
      <geometry name="RLowLeg_visual">
        <mesh filename="package://walkman_urdf/meshes/KneePitchCalf.STL" scale="0.001 0.001 0.001"/>
      </geometry>
      <material name="dark_grey"/>
    </visual>
    <collision>
      <origin rpy="0 0 0" xyz="0 0 0"/>
      <geometry name="RLowLeg_collision">
        <mesh filename="package://walkman_urdf/meshes/simple/KneePitchCalf.STL" scale="0.001 0.001 0.001"/>
      </geometry>
    </collision>
  </link>
  <link name="RFootmot">
    <inertial>
      <origin rpy="0 0 0" xyz="-0.022024173 0.0025677238 0.00094588455"/>
      <mass value="3.2844159"/>
      <inertia ixx="0.0075550679" ixy="0.00067488292" ixz="5.8332889e-05" iyy="0.011241163" iyz="-0.00014552081" izz="0.013391865"/>
    </inertial>
    <visual>
      <origin rpy="0 0 0" xyz="0 0 0"/>
      <geometry name="RFootmot_visual">
        <mesh filename="package://walkman_urdf/meshes/AnklePitch.STL" scale="0.001 0.001 0.001"/>
      </geometry>
      <material name="dark_grey"/>
    </visual>
    <collision>
      <origin rpy="0 0 0" xyz="0 0 0"/>
      <geometry name="RFootmot_collision">
        <mesh filename="package://walkman_urdf/meshes/simple/AnklePitch.STL" scale="0.001 0.001 0.001"/>
      </geometry>
    </collision>
  </link>
  <link name="RFoot">
    <inertial>
      <origin rpy="0 0 0" xyz="-0.00653584 -0.00479384 -0.10180375"/>
      <mass value="3.42638110"/>
      <inertia ixx="0.01032886" ixy="-0.00016407" ixz="-0.00201294" iyy="0.02854025" iyz="0.00046315" izz="0.02799499"/>
    </inertial>
    <visual>
      <origin rpy="0 0 0" xyz="0 0 0"/>
      <geometry name="RFoot_visual">
        <mesh filename="package://walkman_urdf/meshes/Foot.STL" scale="0.001 0.001 0.001"/>
      </geometry>
      <material name="dark_grey"/>
    </visual>
    <collision>
      <origin rpy="0 0 0" xyz="0.005 -0.01 -0.1359"/>
      <geometry>
        <box size="0.32 0.16 0.015"/>
      </geometry>
    </collision>
  </link>
  <!-- ********************LEFT LEG******************** -->
  <link name="LHipMot">
    <inertial>
      <origin rpy="0 0 0" xyz="-0.10348188 0.10919813 -0.064924056"/>
      <mass value="3.7958197"/>
      <inertia ixx="0.015639017" ixy="-0.0018504661" ixz="0.0023907793" iyy="0.023519749" iyz="0.0023303162" izz="0.020953643"/>
    </inertial>
    <visual>
      <origin rpy="0 0 0" xyz="0 0 0"/>
      <geometry name="LHipMot_visual">
        <mesh filename="package://walkman_urdf/meshes/HipRoll.STL" scale="0.001 -0.001 0.001"/>
      </geometry>
      <material name="dark_grey"/>
    </visual>
    <collision>
      <origin rpy="0 0 0" xyz="0 0 0"/>
      <geometry name="LHipMot_collision">
        <mesh filename="package://walkman_urdf/meshes/simple/HipRoll.STL" scale="0.001 -0.001 0.001"/>
      </geometry>
    </collision>
  </link>
  <link name="LThighUpLeg">
    <inertial>
      <origin rpy="0 0 0" xyz="-0.0052929709 0.022561833 0.0056701669"/>
      <mass value="3.2402068"/>
      <inertia ixx="0.010102097" ixy="-0.00010858487" ixz="0.00025291395" iyy="0.0067147" iyz="-8.3447072e-05" izz="0.01048513"/>
    </inertial>
    <visual>
      <origin rpy="0 0 0" xyz="0 0 0"/>
      <geometry name="LThighUpLeg_visual">
        <mesh filename="package://walkman_urdf/meshes/HipYaw.STL" scale="0.001 -0.001 0.001"/>
      </geometry>
      <material name="dark_grey"/>
    </visual>
    <collision>
      <origin rpy="0 0 0" xyz="0 0 0"/>
      <geometry name="LThighUpLeg_collision">
        <mesh filename="package://walkman_urdf/meshes/simple/HipYaw.STL" scale="0.001 -0.001 0.001"/>
      </geometry>
    </collision>
  </link>
  <link name="LThighLowLeg">
    <inertial>
      <origin rpy="0 0 0" xyz="0.037746286 0.028539939 -0.19310133"/>
      <mass value="5.0950736"/>
      <inertia ixx="0.051607858" ixy="-0.0022253472" ixz="0.002452979" iyy="0.044349153" iyz="0.0041006942" izz="0.023374453"/>
    </inertial>
    <visual>
      <origin rpy="0 0 0" xyz="0 0 0"/>
      <geometry name="LThighLowLeg_visual">
        <mesh filename="package://walkman_urdf/meshes/HipPitch.STL" scale="0.001 -0.001 0.001"/>
      </geometry>
      <material name="grey"/>
    </visual>
    <collision>
      <origin rpy="0 0 0" xyz="0 0 0"/>
      <geometry name="LThighLowLeg_collision">
        <mesh filename="package://walkman_urdf/meshes/simple/HipPitch.STL" scale="0.001 -0.001 0.001"/>
      </geometry>
    </collision>
  </link>
  <link name="LLowLeg">
    <inertial>
      <origin rpy="0 0 0" xyz="-0.0050828668 -0.0037732093 -0.072605017"/>
      <mass value="5.6495309"/>
      <inertia ixx="0.10535542" ixy="0.00058199221" ixz="0.0016743598" iyy="0.097857796" iyz="0.0033770181" izz="0.020854086"/>
    </inertial>
    <visual>
      <origin rpy="0 0 0" xyz="0 0 0"/>
      <geometry name="LLowLeg_visual">
        <mesh filename="package://walkman_urdf/meshes/KneePitchCalf.STL" scale="0.001 -0.001 0.001"/>
      </geometry>
      <material name="dark_grey"/>
    </visual>
    <collision>
      <origin rpy="0 0 0" xyz="0 0 0"/>
      <geometry name="LLowLeg_collision">
        <mesh filename="package://walkman_urdf/meshes/simple/KneePitchCalf.STL" scale="0.001 -0.001 0.001"/>
      </geometry>
    </collision>
  </link>
  <link name="LFootmot">
    <inertial>
      <origin rpy="0 0 0" xyz="-0.022024173 -0.0025677238 0.00094588455"/>
      <mass value="3.2844159"/>
      <inertia ixx="0.0075550679" ixy="-0.00067488292" ixz="5.8332889e-05" iyy="0.011241163" iyz="0.00014552081" izz="0.013391865"/>
    </inertial>
    <visual>
      <origin rpy="0 0 0" xyz="0 0 0"/>
      <geometry name="LFootmot_visual">
        <mesh filename="package://walkman_urdf/meshes/AnklePitch.STL" scale="0.001 -0.001 0.001"/>
      </geometry>
      <material name="dark_grey"/>
    </visual>
    <collision>
      <origin rpy="0 0 0" xyz="0 0 0"/>
      <geometry name="LFootmot_collision">
        <mesh filename="package://walkman_urdf/meshes/simple/AnklePitch.STL" scale="0.001 -0.001 0.001"/>
      </geometry>
    </collision>
  </link>
  <link name="LFoot">
    <inertial>
      <origin rpy="0 0 0" xyz="-0.00653584 0.00479384 -0.10180375"/>
      <mass value="3.42638110"/>
      <inertia ixx="0.01032886" ixy="0.00016407" ixz="-0.00201294" iyy="0.02854025" iyz="-0.00046315" izz="0.02799499"/>
    </inertial>
    <visual>
      <origin rpy="0 0 0" xyz="0 0 0"/>
      <geometry name="LFoot_visual">
        <mesh filename="package://walkman_urdf/meshes/Foot.STL" scale="0.001 -0.001 0.001"/>
      </geometry>
      <material name="dark_grey"/>
    </visual>
    <collision>
      <origin rpy="0 0 0" xyz="0.005 0.01 -0.1359"/>
      <geometry>
        <box size="0.32 0.16 0.015"/>
      </geometry>
    </collision>
  </link>
  <!-- JOINTS -->
  <!-- ********************RIGHT LEG******************** -->
  <joint name="RHipLat" type="revolute">
    <parent link="Waist"/>
    <child link="RHipMot"/>
    <origin rpy="0 0 0" xyz="0.1569 -0.06 -0.108"/>
    <axis xyz="1 0 0"/>
    <limit effort="400" lower="-0.872664625995" upper="0.698131700796" velocity="6.283"/>
    <dynamics damping="3.0" friction="0"/>
  </joint>
  <joint name="RHipYaw" type="revolute">
    <parent link="RHipMot"/>
    <child link="RThighUpLeg"/>
    <origin rpy="0 0 0" xyz="-0.0889 -0.121032 -0.217872"/>
    <axis xyz="0 0 1"/>
    <limit effort="140" lower="-1.57079632679" upper="0.872664625995" velocity="6.283"/>
    <dynamics damping="3.0" friction="0"/>
  </joint>
  <joint name="RHipSag" type="revolute">
    <parent link="RThighUpLeg"/>
    <child link="RThighLowLeg"/>
    <origin rpy="0 0 0" xyz="0.0 0.0 0.0"/>
    <axis xyz="0 1 0"/>
    <limit effort="400" lower="-2.09439510239" upper="1.04719755119" velocity="6.283"/>
    <dynamics damping="3.0" friction="0"/>
  </joint>
  <joint name="RKneeSag" type="revolute">
    <parent link="RThighLowLeg"/>
    <child link="RLowLeg"/>
    <origin rpy="0 0 0" xyz="0.0 0.0 -0.356"/>
    <axis xyz="0 1 0"/>
    <limit effort="400" lower="0.0" upper="2.44346095279" velocity="6.283"/>
    <dynamics damping="3.0" friction="0"/>
  </joint>
  <joint name="RAnkSag" type="revolute">
    <parent link="RLowLeg"/>
    <child link="RFootmot"/>
    <origin rpy="0 0 0" xyz="0.0 0.0 -0.4"/>
    <axis xyz="0 1 0"/>
    <limit effort="330" lower="-1.39626340159" upper="0.698131700796" velocity="6.283"/>
    <dynamics damping="3.0" friction="0"/>
  </joint>
  <joint name="RAnkLat" type="revolute">
    <parent link="RFootmot"/>
    <child link="RFoot"/>
    <origin rpy="0 0 0" xyz="0.0 0.0 0.0"/>
    <axis xyz="1 0 0"/>
    <limit effort="210" lower="-0.785398163396" upper="0.785398163396" velocity="6.283"/>
    <dynamics damping="3.0" friction="0"/>
  </joint>
  <!-- ********************LEFT LEG******************** -->
  <joint name="LHipLat" type="revolute">
    <parent link="Waist"/>
    <child link="LHipMot"/>
    <origin rpy="0 0 0" xyz="0.1569 0.06 -0.108"/>
    <axis xyz="1 0 0"/>
    <limit effort="400" lower="-0.698131700796" upper="0.872664625995" velocity="6.283"/>
    <dynamics damping="3.0" friction="0"/>
  </joint>
  <joint name="LHipYaw" type="revolute">
    <parent link="LHipMot"/>
    <child link="LThighUpLeg"/>
    <origin rpy="0 0 0" xyz="-0.0889 0.121032 -0.217872"/>
    <axis xyz="0 0 1"/>
    <limit effort="140" lower="-0.872664625995" upper="1.57079632679" velocity="6.283"/>
    <dynamics damping="3.0" friction="0"/>
  </joint>
  <joint name="LHipSag" type="revolute">
    <parent link="LThighUpLeg"/>
    <child link="LThighLowLeg"/>
    <origin rpy="0 0 0" xyz="0.0 0.0 0.0"/>
    <axis xyz="0 1 0"/>
    <limit effort="400" lower="-2.09439510239" upper="1.04719755119" velocity="6.283"/>
    <dynamics damping="3.0" friction="0"/>
  </joint>
  <joint name="LKneeSag" type="revolute">
    <parent link="LThighLowLeg"/>
    <child link="LLowLeg"/>
    <origin rpy="0 0 0" xyz="0.0 0.0 -0.356"/>
    <axis xyz="0 1 0"/>
    <limit effort="400" lower="0.0" upper="2.44346095279" velocity="6.283"/>
    <dynamics damping="3.0" friction="0"/>
  </joint>
  <joint name="LAnkSag" type="revolute">
    <parent link="LLowLeg"/>
    <child link="LFootmot"/>
    <origin rpy="0 0 0" xyz="0.0 0.0 -0.4"/>
    <axis xyz="0 1 0"/>
    <limit effort="330" lower="-1.39626340159" upper="0.698131700796" velocity="6.283"/>
    <dynamics damping="3.0" friction="0"/>
  </joint>
  <joint name="LAnkLat" type="revolute">
    <parent link="LFootmot"/>
    <child link="LFoot"/>
    <origin rpy="0 0 0" xyz="0.0 0.0 0.0"/>
    <axis xyz="1 0 0"/>
    <limit effort="210" lower="-0.785398163396" upper="0.785398163396" velocity="6.283"/>
    <dynamics damping="3.0" friction="0"/>
  </joint>
  <link name="l_ankle"/>
  <link name="r_ankle"/>
  <link name="l_sole"/>
  <link name="r_sole"/>
  <joint name="l_ankle_joint" type="fixed">
    <parent link="LFoot"/>
    <child link="l_ankle"/>
    <origin rpy="0 0 0" xyz="0 0 0"/>
  </joint>
  <joint name="r_ankle_joint" type="fixed">
    <parent link="RFoot"/>
    <child link="r_ankle"/>
    <origin rpy="0 0 0" xyz="0 0 0"/>
  </joint>
  <joint name="l_sole_joint" type="fixed">
    <parent link="LFoot"/>
    <child link="l_sole"/>
    <origin rpy="0 0 0" xyz="0 0 -0.1435"/>
  </joint>
  <joint name="r_sole_joint" type="fixed">
    <parent link="RFoot"/>
    <child link="r_sole"/>
    <origin rpy="0 0 0" xyz="0 0 -0.1435"/>
  </joint>
  <!-- macro for reference frames in foot -->
  <!-- macro for one reference frame in foot -->
  <link name="l_foot_upper_right_link"/>
  <joint name="l_foot_upper_right_joint" type="fixed">
    <origin rpy="0 0 0" xyz="0.16 -0.07 0"/>
    <parent link="l_sole"/>
    <child link="l_foot_upper_right_link"/>
  </joint>
  <!-- macro for one reference frame in foot -->
  <link name="l_foot_upper_left_link"/>
  <joint name="l_foot_upper_left_joint" type="fixed">
    <origin rpy="0 0 0" xyz="0.16 0.09 0"/>
    <parent link="l_sole"/>
    <child link="l_foot_upper_left_link"/>
  </joint>
  <!-- macro for one reference frame in foot -->
  <link name="l_foot_lower_right_link"/>
  <joint name="l_foot_lower_right_joint" type="fixed">
    <origin rpy="0 0 0" xyz="-0.16 -0.07 0"/>
    <parent link="l_sole"/>
    <child link="l_foot_lower_right_link"/>
  </joint>
  <!-- macro for one reference frame in foot -->
  <link name="l_foot_lower_left_link"/>
  <joint name="l_foot_lower_left_joint" type="fixed">
    <origin rpy="0 0 0" xyz="-0.16 0.09 0"/>
    <parent link="l_sole"/>
    <child link="l_foot_lower_left_link"/>
  </joint>
  <!-- macro for reference frames in foot -->
  <!-- macro for one reference frame in foot -->
  <link name="r_foot_upper_right_link"/>
  <joint name="r_foot_upper_right_joint" type="fixed">
    <origin rpy="0 0 0" xyz="0.16 0.07 0"/>
    <parent link="r_sole"/>
    <child link="r_foot_upper_right_link"/>
  </joint>
  <!-- macro for one reference frame in foot -->
  <link name="r_foot_upper_left_link"/>
  <joint name="r_foot_upper_left_joint" type="fixed">
    <origin rpy="0 0 0" xyz="0.16 -0.09 0"/>
    <parent link="r_sole"/>
    <child link="r_foot_upper_left_link"/>
  </joint>
  <!-- macro for one reference frame in foot -->
  <link name="r_foot_lower_right_link"/>
  <joint name="r_foot_lower_right_joint" type="fixed">
    <origin rpy="0 0 0" xyz="-0.16 0.07 0"/>
    <parent link="r_sole"/>
    <child link="r_foot_lower_right_link"/>
  </joint>
  <!-- macro for one reference frame in foot -->
  <link name="r_foot_lower_left_link"/>
  <joint name="r_foot_lower_left_joint" type="fixed">
    <origin rpy="0 0 0" xyz="-0.16 -0.09 0"/>
    <parent link="r_sole"/>
    <child link="r_foot_lower_left_link"/>
  </joint>
  <!-- LINKS -->
  <!-- This links are defined in order to be compliant with http://www.ros.org/reps/rep-0120.html#coordinate-frames
and to define the end effectors of the robot-->
  <!-- The coordinate frame called torso is attached to the lowest body of the model which is a parent of l_gripper, r_gripper and gaze. -->
  <link name="DWL">
    <inertial>
      <origin rpy="0 0 0" xyz="-0.013438629 -2.4995993e-05 0.073562799"/>
      <mass value="2.4309068"/>
      <inertia ixx="0.016702798" ixy="3.5908153e-05" ixz="-0.0041709274" iyy="0.019440925" iyz="1.1578036e-05" izz="0.0057721068"/>
    </inertial>
    <visual>
      <origin rpy="0 0 0" xyz="0.0 0.0 0.0"/>
      <geometry name="DWL_visual">
        <mesh filename="package://walkman_urdf/meshes/TorsoRoll.STL" scale="0.001 0.001 0.001"/>
      </geometry>
      <material name="dark_grey"/>
    </visual>
    <collision>
      <origin rpy="0 0 0" xyz="0.0 0.0 0.0"/>
      <geometry name="DWL_collision">
        <mesh filename="package://walkman_urdf/meshes/simple/TorsoRoll.STL" scale="0.001 0.001 0.001"/>
      </geometry>
    </collision>
  </link>
  <link name="DWYTorso">
    <inertial>
      <origin rpy="0 0 0" xyz="-0.059646212 0.0014305062 0.042741527"/>
      <mass value="1.2512295e+01"/>
      <inertia ixx="0.21021617" ixy="-0.00015527214" ixz="-0.050216602" iyy="0.19982996" iyz="-0.00029204792" izz="0.14025094"/>
    </inertial>
    <visual>
      <origin rpy="0 0 0" xyz="0.0 0.0 0.0"/>
      <geometry name="DWYTorso_visual">
        <mesh filename="package://walkman_urdf/meshes/Chest.STL" scale="0.001 0.001 0.001"/>
      </geometry>
      <material name="blue"/>
    </visual>
    <collision>
      <origin rpy="0 0 0" xyz="0.0 0.0 0.0"/>
      <geometry name="DWYTorso_collision">
        <mesh filename="package://walkman_urdf/meshes/simple/Chest.STL" scale="0.001 0.001 0.001"/>
      </geometry>
    </collision>
  </link>
  <!--link name="torso"/-->
  <!-- JOINTS -->
  <!--joint name="torso_joint" type="fixed">
    <parent link="DWYTorso"/>
    <child link="torso"/>
    <origin xyz="0.0 0 0.0" rpy="0 0 0" /> 
</joint-->
  <joint name="WaistLat" type="revolute">
    <parent link="Waist"/>
    <child link="DWL"/>
    <origin rpy="0 0 0" xyz="0.0596 0 0.0"/>
    <axis xyz="1 0 0"/>
    <limit effort="120" lower="-0.610865238196" upper="0.610865238196" velocity="6.283"/>
    <dynamics damping="3.0" friction="0"/>
  </joint>
  <joint name="WaistYaw" type="revolute">
    <parent link="DWL"/>
    <child link="DWYTorso"/>
    <origin rpy="0 0 0" xyz="0.0088 0 0.22215"/>
    <axis xyz="0 0 1"/>
    <limit effort="120" lower="-1.74532925199" upper="1.74532925199" velocity="6.283"/>
    <dynamics damping="3.0" friction="0"/>
  </joint>
  <!-- LINKS -->
  <link name="NeckYaw">
    <inertial>
      <origin rpy="0 0 0" xyz="0.00017665124 -0.00056962982 0.009696191 "/>
      <mass value="5.9544662e-01"/>
      <inertia ixx="0.00044402452" ixy="-4.7573996e-08" ixz="1.2703055e-07" iyy="0.00036958221" iyz="5.6524326e-06" izz="0.00027123782"/>
    </inertial>
    <visual>
      <origin rpy="0 0 0" xyz="0.0 0.0 0.0"/>
      <geometry name="NeckYaw_visual">
        <mesh filename="package://walkman_urdf/meshes/NeckYaw.STL" scale="0.001 0.001 0.001"/>
      </geometry>
      <material name="grey"/>
    </visual>
    <collision>
      <origin rpy="0 0 0" xyz="0.0 0.0 0.0"/>
      <geometry name="NeckYaw_collision">
        <mesh filename="package://walkman_urdf/meshes/simple/NeckYaw.STL" scale="0.001 0.001 0.001"/>
      </geometry>
    </collision>
  </link>
  <link name="NeckPitch">
    <inertial>
      <origin rpy="0 0 0" xyz="0.0065724785 -0.034569915 0.11402826"/>
      <mass value="3.1388490"/>
      <inertia ixx="0.022067171" ixy="-3.2510922e-05" ixz="-0.001205899" iyy="0.019140289" iyz="-9.6672078e-05" izz="0.021334662"/>
    </inertial>
    <visual>
      <origin rpy="0 0 0" xyz="0.0 0.0 0.0"/>
      <geometry name="NeckPitch_visual">
        <mesh filename="package://walkman_urdf/meshes/NeckPitch.STL" scale="0.001 0.001 0.001"/>
      </geometry>
      <material name="grey"/>
    </visual>
    <collision>
      <origin rpy="0 0 0" xyz="0.0 0.0 0.0"/>
      <geometry name="NeckPitch_collision">
        <mesh filename="package://walkman_urdf/meshes/simple/NeckPitch.STL" scale="0.001 0.001 0.001"/>
      </geometry>
    </collision>
  </link>
  <!-- JOINTS -->
  <joint name="NeckYawj" type="revolute">
    <parent link="DWYTorso"/>
    <child link="NeckYaw"/>
    <origin rpy="0 0 0" xyz="0.016 0 0.238292"/>
    <axis xyz="0 0 1"/>
    <limit effort="120" lower="-0.610865238196" upper="0.610865238196" velocity="6.283"/>
    <dynamics damping="3.0" friction="0"/>
  </joint>
  <joint name="NeckPitchj" type="revolute">
    <parent link="NeckYaw"/>
    <child link="NeckPitch"/>
    <origin rpy="0 0 0" xyz="0 0.03425 0.027"/>
    <axis xyz="0 1 0"/>
    <limit effort="120" lower="-0.261799387798" upper="1.04719755119" velocity="6.283"/>
    <dynamics damping="3.0" friction="0"/>
  </joint>
  <!-- RIGHT ARM -->
  <link name="RShp">
    <inertial>
      <origin rpy="0 0 0" xyz="-0.0074457212 -0.03410796 0.00010978102"/>
      <mass value="1.9628675"/>
      <inertia ixx="0.0053547717" ixy="-0.00036428926" ixz="1.5089568e-05" iyy="0.0033923328" iyz="-5.5692312e-05" izz="0.0068921413"/>
    </inertial>
    <visual>
      <origin rpy="0 0 0" xyz="0 0 0"/>
      <geometry name="RShp_visual">
        <mesh filename="package://walkman_urdf/meshes/ShoulderPitch.STL" scale="0.001 0.001 0.001"/>
      </geometry>
      <material name="dark_grey"/>
    </visual>
    <collision>
      <origin rpy="0 0 0" xyz="0 0 0"/>
      <geometry name="RShp_collision">
        <mesh filename="package://walkman_urdf/meshes/simple/ShoulderPitch.STL" scale="0.001 0.001 0.001"/>
      </geometry>
    </collision>
  </link>
  <link name="RShr">
    <inertial>
      <origin rpy="0 0 0" xyz="0.058142302 -5.7450803e-05 -0.077477683"/>
      <mass value="1.8595811"/>
      <inertia ixx="0.013776643" ixy="-3.7788675e-05" ixz="0.0037690171" iyy="0.015677464" iyz="9.4893549e-06" izz="0.0046317657"/>
    </inertial>
    <visual>
      <origin rpy="0 0 0" xyz="0 0 0"/>
      <geometry name="RShr_visual">
        <mesh filename="package://walkman_urdf/meshes/ShoulderRoll.STL" scale="0.001 0.001 0.001"/>
      </geometry>
      <material name="dark_grey"/>
    </visual>
    <collision>
      <origin rpy="0 0 0" xyz="0 0 0"/>
      <geometry name="RShr_collision">
        <mesh filename="package://walkman_urdf/meshes/simple/ShoulderRoll.STL" scale="0.001 0.001 0.001"/>
      </geometry>
    </collision>
  </link>
  <link name="RShy">
    <inertial>
      <origin rpy="0 0 0" xyz="0.014625194 -0.0008172672 -0.028333545"/>
      <mass value="1.6678109"/>
      <inertia ixx="0.0064480435" ixy="0.00015639093" ixz="0.0012205359" iyy="0.0073372077" iyz="-8.9941532e-05" izz="0.0036738448"/>
    </inertial>
    <visual>
      <origin rpy="0 0 0" xyz="0 0 0"/>
      <geometry name="RShy_visual">
        <mesh filename="package://walkman_urdf/meshes/ShoulderYaw.STL" scale="0.001 0.001 0.001"/>
      </geometry>
      <material name="dark_grey"/>
    </visual>
    <collision>
      <origin rpy="0 0 0" xyz="0 0 0"/>
      <geometry name="RShy_collision">
        <mesh filename="package://walkman_urdf/meshes/simple/ShoulderYaw.STL" scale="0.001 0.001 0.001"/>
      </geometry>
    </collision>
  </link>
  <link name="RElb">
    <inertial>
      <origin rpy="0 0 0" xyz="-0.0076833067 0.040302205 -0.043492779"/>
      <mass value="1.3157289"/>
      <inertia ixx="0.004330394" ixy="0.00011737391" ixz="-0.00041923199" iyy="0.0038539919" iyz="0.00079573038" izz="0.0017594689"/>
    </inertial>
    <visual>
      <origin rpy="0 0 0" xyz="0 0 0"/>
      <geometry name="RElb_visual">
        <mesh filename="package://walkman_urdf/meshes/Elbow.STL" scale="0.001 0.001 0.001"/>
      </geometry>
      <material name="dark_grey"/>
    </visual>
    <collision>
      <origin rpy="0 0 0" xyz="0 0 0"/>
      <geometry name="RElb_collision">
        <mesh filename="package://walkman_urdf/meshes/simple/Elbow.STL" scale="0.001 0.001 0.001"/>
      </geometry>
    </collision>
  </link>
  <link name="RForearm">
    <inertial>
      <origin rpy="0 0 0" xyz="-0.00011079615 -0.011590836 -0.07816026"/>
      <mass value="1.4908547"/>
      <inertia ixx="0.0085692128" ixy="-1.7856252e-05" ixz="1.9379365e-05" iyy="0.0077454159" iyz="0.00032860094" izz="0.0027441921"/>
    </inertial>
    <visual>
      <origin rpy="0 0 0" xyz="0 0 0"/>
      <geometry name="RForearm_visual">
        <mesh filename="package://walkman_urdf/meshes/Forearm.STL" scale="0.001 0.001 0.001"/>
      </geometry>
      <material name="dark_grey"/>
    </visual>
    <collision>
      <origin rpy="0 0 0" xyz="0 0 0"/>
      <geometry name="RForearm_collision">
        <mesh filename="package://walkman_urdf/meshes/simple/Forearm.STL" scale="0.001 0.001 0.001"/>
      </geometry>
    </collision>
  </link>
  <link name="RWrMot2">
    <inertial>
      <origin rpy="0 0 0" xyz="-4.6502396e-06 0.038014094 -0.069926878"/>
      <mass value="1.1263612"/>
      <inertia ixx="0.0051871784" ixy="-2.724437e-05" ixz="2.2833496e-06" iyy="0.0048037789" iyz="0.00072165653" izz="0.0012771388"/>
    </inertial>
    <visual>
      <origin rpy="0 0 0" xyz="0 0 0"/>
      <geometry name="RWrMot2_visual">
        <mesh filename="package://walkman_urdf/meshes/ForearmPitch.STL" scale="0.001 0.001 0.001"/>
      </geometry>
      <material name="dark_grey"/>
    </visual>
    <collision>
      <origin rpy="0 0 0" xyz="0 0 0"/>
      <geometry name="RWrMot2_collision">
        <mesh filename="package://walkman_urdf/meshes/simple/ForearmPitch.STL" scale="0.001 0.001 0.001"/>
      </geometry>
    </collision>
  </link>
  <link name="RWrMot3">
    <inertial>
      <origin rpy="0 0 0" xyz="0 0 0.03127057"/>
      <mass value="2.7966428e-01"/>
      <inertia ixx="0.00014415192" ixy="9.8651826e-08" ixz="0" iyy="0.0001441701" iyz="0" izz="6.0500616e-05"/>
    </inertial>
    <visual>
      <origin rpy="0 0 0" xyz="0 0 0"/>
      <geometry name="RWrMot3_visual">
        <mesh filename="package://walkman_urdf/meshes/ForearmYaw.STL" scale="0.001 0.001 0.001"/>
      </geometry>
      <material name="blue"/>
    </visual>
    <collision>
      <origin rpy="0 0 0" xyz="0 0 0"/>
      <geometry name="RWrMot3_collision">
        <mesh filename="package://walkman_urdf/meshes/simple/ForearmYaw.STL" scale="0.001 0.001 0.001"/>
      </geometry>
    </collision>
  </link>
  <joint name="RShSag" type="revolute">
    <parent link="DWYTorso"/>
    <child link="RShp"/>
    <origin rpy="-0.174533 0 0.5235988" xyz="0.0457475 -0.169137 0.155126"/>
    <axis xyz="0 1 0"/>
    <limit effort="147" lower="-3.40339204138" upper="1.65806278939" velocity="6.283"/>
    <dynamics damping="3.0" friction="0"/>
  </joint>
  <joint name="RShLat" type="revolute">
    <parent link="RShp"/>
    <child link="RShr"/>
    <origin rpy="0.1745327 0 0" xyz="-0.09015 -0.062 0"/>
    <axis xyz="1 0 0"/>
    <limit effort="120" lower="-3.49065850398" upper="0" velocity="6.283"/>
    <dynamics damping="3.0" friction="0"/>
  </joint>
  <joint name="RShYaw" type="revolute">
    <parent link="RShr"/>
    <child link="RShy"/>
    <origin rpy="0 0 0" xyz="0.09015 0 -0.21815"/>
    <axis xyz="0 0 1"/>
    <limit effort="147" lower="-2.61799387799" upper="2.61799387799" velocity="6.283"/>
    <dynamics damping="3.0" friction="0"/>
  </joint>
  <joint name="RElbj" type="revolute">
    <parent link="RShy"/>
    <child link="RElb"/>
    <origin rpy="0 0 0" xyz="0.045 -0.05515 -0.074"/>
    <axis xyz="0 1 0"/>
    <limit effort="147" lower="-2.96705972838" upper="0.593411945677" velocity="6.283"/>
    <dynamics damping="3.0" friction="0"/>
  </joint>
  <joint name="RForearmPlate" type="revolute">
    <parent link="RElb"/>
    <child link="RForearm"/>
    <origin rpy="0 0 0" xyz="-0.015 0.05515 -0.095"/>
    <axis xyz="0 0 1"/>
    <limit effort="55" lower="-2.61799387799" upper="2.61799387799" velocity="6.283"/>
    <dynamics damping="0.03" friction="0"/>
  </joint>
  <joint name="RWrj1" type="revolute">
    <parent link="RForearm"/>
    <child link="RWrMot2"/>
    <origin rpy="0 0 0" xyz="0 -0.049 -0.156"/>
    <axis xyz="0 1 0"/>
    <limit effort="55" lower="-1.57079632679" upper="1.57079632679" velocity="6.283"/>
    <dynamics damping="0.03" friction="0"/>
  </joint>
  <joint name="RWrj2" type="revolute">
    <parent link="RWrMot2"/>
    <child link="RWrMot3"/>
    <origin rpy="0 0 0" xyz="0 0.049 -0.174"/>
    <axis xyz="0 0 1"/>
    <limit effort="27" lower="-2.61799387799" upper="2.61799387799" velocity="6.283"/>
    <dynamics damping="0.03" friction="0"/>
  </joint>
  <!-- LEFT ARM -->
  <link name="LShp">
    <inertial>
      <origin rpy="0 0 0" xyz="-0.0074457212 0.03410796 0.00010978102"/>
      <mass value="1.9628675"/>
      <inertia ixx="0.0053547717" ixy="0.00036428926" ixz="1.5089568e-05" iyy="0.0033923328" iyz="5.5692312e-05" izz="0.0068921413"/>
    </inertial>
    <visual>
      <origin rpy="0 0 0" xyz="0 0 0"/>
      <geometry name="LShp_visual">
        <mesh filename="package://walkman_urdf/meshes/ShoulderPitch.STL" scale="0.001 -0.001 0.001"/>
      </geometry>
      <material name="dark_grey"/>
    </visual>
    <collision>
      <origin rpy="0 0 0" xyz="0 0 0"/>
      <geometry name="LShp_collision">
        <mesh filename="package://walkman_urdf/meshes/simple/ShoulderPitch.STL" scale="0.001 -0.001 0.001"/>
      </geometry>
    </collision>
  </link>
  <link name="LShr">
    <inertial>
      <origin rpy="0 0 0" xyz="0.058142302 5.7450803e-05 -0.077477683"/>
      <mass value="1.8595811"/>
      <inertia ixx="0.013776643" ixy="3.7788675e-05" ixz="0.0037690171" iyy="0.015677464" iyz="-9.4893549e-06" izz="0.0046317657"/>
    </inertial>
    <visual>
      <origin rpy="0 0 0" xyz="0 0 0"/>
      <geometry name="LShr_visual">
        <mesh filename="package://walkman_urdf/meshes/ShoulderRoll.STL" scale="0.001 -0.001 0.001"/>
      </geometry>
      <material name="dark_grey"/>
    </visual>
    <collision>
      <origin rpy="0 0 0" xyz="0 0 0"/>
      <geometry name="LShr_collision">
        <mesh filename="package://walkman_urdf/meshes/simple/ShoulderRoll.STL" scale="0.001 -0.001 0.001"/>
      </geometry>
    </collision>
  </link>
  <link name="LShy">
    <inertial>
      <origin rpy="0 0 0" xyz="0.014625194 0.0008172672 -0.028333545"/>
      <mass value="1.6678109"/>
      <inertia ixx="0.0064480435" ixy="-0.00015639093" ixz="0.0012205359" iyy="0.0073372077" iyz="8.9941532e-05" izz="0.0036738448"/>
    </inertial>
    <visual>
      <origin rpy="0 0 0" xyz="0 0 0"/>
      <geometry name="LShy_visual">
        <mesh filename="package://walkman_urdf/meshes/ShoulderYaw.STL" scale="0.001 -0.001 0.001"/>
      </geometry>
      <material name="dark_grey"/>
    </visual>
    <collision>
      <origin rpy="0 0 0" xyz="0 0 0"/>
      <geometry name="LShy_collision">
        <mesh filename="package://walkman_urdf/meshes/simple/ShoulderYaw.STL" scale="0.001 -0.001 0.001"/>
      </geometry>
    </collision>
  </link>
  <link name="LElb">
    <inertial>
      <origin rpy="0 0 0" xyz="-0.0076833067 -0.040302205 -0.043492779"/>
      <mass value="1.3157289"/>
      <inertia ixx="0.004330394" ixy="-0.00011737391" ixz="-0.00041923199" iyy="0.0038539919" iyz="-0.00079573038" izz="0.0017594689"/>
    </inertial>
    <visual>
      <origin rpy="0 0 0" xyz="0 0 0"/>
      <geometry name="LElb_visual">
        <mesh filename="package://walkman_urdf/meshes/Elbow.STL" scale="0.001 -0.001 0.001"/>
      </geometry>
      <material name="dark_grey"/>
    </visual>
    <collision>
      <origin rpy="0 0 0" xyz="0 0 0"/>
      <geometry name="LElb_collision">
        <mesh filename="package://walkman_urdf/meshes/simple/Elbow.STL" scale="0.001 -0.001 0.001"/>
      </geometry>
    </collision>
  </link>
  <link name="LForearm">
    <inertial>
      <origin rpy="0 0 0" xyz="-0.00011079615 0.011590836 -0.07816026"/>
      <mass value="1.4908547"/>
      <inertia ixx="0.0085692128" ixy="1.7856252e-05" ixz="1.9379365e-05" iyy="0.0077454159" iyz="-0.00032860094" izz="0.0027441921"/>
    </inertial>
    <visual>
      <origin rpy="0 0 0" xyz="0 0 0"/>
      <geometry name="LForearm_visual">
        <mesh filename="package://walkman_urdf/meshes/Forearm.STL" scale="0.001 -0.001 0.001"/>
      </geometry>
      <material name="dark_grey"/>
    </visual>
    <collision>
      <origin rpy="0 0 0" xyz="0 0 0"/>
      <geometry name="LForearm_collision">
        <mesh filename="package://walkman_urdf/meshes/simple/Forearm.STL" scale="0.001 -0.001 0.001"/>
      </geometry>
    </collision>
  </link>
  <link name="LWrMot2">
    <inertial>
      <origin rpy="0 0 0" xyz="-4.6502396e-06 -0.038014094 -0.069926878"/>
      <mass value="1.1263612"/>
      <inertia ixx="0.0051871784" ixy="2.724437e-05" ixz="2.2833496e-06" iyy="0.0048037789" iyz="-0.00072165653" izz="0.0012771388"/>
    </inertial>
    <visual>
      <origin rpy="0 0 0" xyz="0 0 0"/>
      <geometry name="LWrMot2_visual">
        <mesh filename="package://walkman_urdf/meshes/ForearmPitch.STL" scale="0.001 -0.001 0.001"/>
      </geometry>
      <material name="dark_grey"/>
    </visual>
    <collision>
      <origin rpy="0 0 0" xyz="0 0 0"/>
      <geometry name="LWrMot2_collision">
        <mesh filename="package://walkman_urdf/meshes/simple/ForearmPitch.STL" scale="0.001 -0.001 0.001"/>
      </geometry>
    </collision>
  </link>
  <link name="LWrMot3">
    <inertial>
      <origin rpy="0 0 0" xyz="0 0 0.03127057"/>
      <mass value="2.7966428e-01"/>
      <inertia ixx="0.00014415192" ixy="9.8651826e-08" ixz="0" iyy="0.0001441701" iyz="0" izz="6.0500616e-05"/>
    </inertial>
    <visual>
      <origin rpy="0 0 0" xyz="0 0 0"/>
      <geometry name="LWrMot3_visual">
        <mesh filename="package://walkman_urdf/meshes/ForearmYaw.STL" scale="0.001 -0.001 0.001"/>
      </geometry>
      <material name="blue"/>
    </visual>
    <collision>
      <origin rpy="0 0 0" xyz="0 0 0"/>
      <geometry name="LWrMot3_collision">
        <mesh filename="package://walkman_urdf/meshes/simple/ForearmYaw.STL" scale="0.001 -0.001 0.001"/>
      </geometry>
    </collision>
  </link>
  <joint name="LShSag" type="revolute">
    <parent link="DWYTorso"/>
    <child link="LShp"/>
    <origin rpy="0.174533 0 -0.5235988" xyz="0.0457475 0.169137 0.155126"/>
    <axis xyz="0 1 0"/>
    <limit effort="147" lower="-3.40339204138" upper="1.65806278939" velocity="6.283"/>
    <dynamics damping="3.0" friction="0"/>
  </joint>
  <joint name="LShLat" type="revolute">
    <parent link="LShp"/>
    <child link="LShr"/>
    <origin rpy="-0.1745327 0 0" xyz="-0.09015 0.062 0"/>
    <axis xyz="1 0 0"/>
    <limit effort="120" lower="0" upper="3.49065850398" velocity="6.283"/>
    <dynamics damping="3.0" friction="0"/>
  </joint>
  <joint name="LShYaw" type="revolute">
    <parent link="LShr"/>
    <child link="LShy"/>
    <origin rpy="0 0 0" xyz="0.09015 0 -0.21815"/>
    <axis xyz="0 0 1"/>
    <limit effort="147" lower="-2.61799387799" upper="2.61799387799" velocity="6.283"/>
    <dynamics damping="3.0" friction="0"/>
  </joint>
  <joint name="LElbj" type="revolute">
    <parent link="LShy"/>
    <child link="LElb"/>
    <origin rpy="0 0 0" xyz="0.045 0.05515 -0.074"/>
    <axis xyz="0 1 0"/>
    <limit effort="147" lower="-2.53072741539" upper="0.349065850398" velocity="6.283"/>
    <dynamics damping="3.0" friction="0"/>
  </joint>
  <joint name="LForearmPlate" type="revolute">
    <parent link="LElb"/>
    <child link="LForearm"/>
    <origin rpy="0 0 0" xyz="-0.015 -0.05515 -0.095"/>
    <axis xyz="0 0 1"/>
    <limit effort="55" lower="-2.61799387799" upper="2.61799387799" velocity="6.283"/>
    <dynamics damping="0.03" friction="0"/>
  </joint>
  <joint name="LWrj1" type="revolute">
    <parent link="LForearm"/>
    <child link="LWrMot2"/>
    <origin rpy="0 0 0" xyz="0 0.049 -0.156"/>
    <axis xyz="0 1 0"/>
    <limit effort="55" lower="-1.57079632679" upper="1.57079632679" velocity="6.283"/>
    <dynamics damping="0.03" friction="0"/>
  </joint>
  <joint name="LWrj2" type="revolute">
    <parent link="LWrMot2"/>
    <child link="LWrMot3"/>
    <origin rpy="0 0 0" xyz="0 -0.049 -0.174"/>
    <axis xyz="0 0 1"/>
    <limit effort="27" lower="-2.61799387799" upper="2.61799387799" velocity="6.283"/>
    <dynamics damping="0.03" friction="0"/>
  </joint>
  <link name="l_wrist"/>
  <link name="r_wrist"/>
  <joint name="l_wrist_joint" type="fixed">
    <parent link="LWrMot3"/>
    <child link="l_wrist"/>
    <origin rpy="0 0 0" xyz="0 0 0"/>
  </joint>
  <joint name="r_wrist_joint" type="fixed">
    <parent link="RWrMot3"/>
    <child link="r_wrist"/>
    <origin rpy="0 0 0" xyz="0 0 0"/>
  </joint>
  <link name="world"/>
  <joint name="reference" type="floating">
    <origin xyz="0.0 0.0 0.0"/>
    <parent link="world"/>
    <child link="base_link"/>
  </joint>
  <link name="l_leg_ft"/>
  <link name="r_leg_ft"/>
  <joint name="l_leg_ft_joint" type="fixed">
    <parent link="LFoot"/>
    <child link="l_leg_ft"/>
    <origin rpy="0 0 0" xyz="0.005 0 -0.107"/>
  </joint>
  <joint name="r_leg_ft_joint" type="fixed">
    <parent link="RFoot"/>
    <child link="r_leg_ft"/>
    <origin rpy="0 0 0" xyz="0.005 0 -0.107"/>
  </joint>
  <!--
	<link name="l_arm_ft"/>
	<link name="r_arm_ft"/>

	<joint name="l_arm_ft_joint" type="fixed">
	    <parent link="LWrMot3"/>
	    <child link="l_arm_ft"/>
	    <origin xyz="0 0 -0.0565" rpy="0 0 0" /> 
	</joint>

	<joint name="r_arm_ft_joint" type="fixed">
	    <parent link="RWrMot3"/>
	    <child link="r_arm_ft"/>
	    <origin xyz="0 0 -0.0565" rpy="0 0 0" /> 
	</joint>



	<link name="l_wrist"/>
	<link name="r_wrist"/>

	<xacro:include filename="$(find bigman_urdf)/urdf/parts/forearms.urdf.xacro" />
       <xacro:if value="${BIGMAN_ADD_RAISING_SUPPORT}">
	       <xacro:include filename="$(find bigman_urdf)/urdf/parts/forearm_reference_frame.urdf.xacro" />
       </xacro:if>

	<xacro:include filename="$(find bigman_urdf)/urdf/parts/soft_hand.urdf.xacro" />

		

-->
  <link name="imu_link">
    <inertial>
      <mass value="0.01"/>
      <origin xyz="0 0 0"/>
      <inertia ixx="1.0E-6" ixy="0" ixz="0" iyy="1.0E-6" iyz="0" izz="1.0E-6"/>
    </inertial>
    <visual>
      <origin rpy="0 0 0" xyz="0 0 0"/>
      <geometry>
        <box size="0.01 0.01 0.01"/>
      </geometry>
    </visual>
  </link>
  <!-- TODO: CHANGE THE ORIGIN OF THE SENSOR ACCORDING TO THE REAL ONE -->
  <joint name="imu_joint" type="fixed">
    <parent link="Waist"/>
    <child link="imu_link"/>
    <origin rpy="0 0 0" xyz="0.116998 2.83129e-05 -0.0478857"/>
  </joint>
</robot>

